Workbook
Name Cablestyle: Print!$AK$50:$AK$59
Name HEIGHT: 'shade check'!$H$11:$I$18
Name m: #REF!
Name X: 'shade check'!$BG$38:$BG$48
Name Y: 'shade check'!$BH$38:$BH$48

Sheet Details
P1: Turn Buckle Size | R1: D Shackle Size | S1: Toggle Size
B2: Sun Safe Shade Sails | I2: Installers
B3: Customer Details | I3: David H | P3: 6mm Hook-Hook | R3: 6mm | S3: 12mm@200mm
B4: Measurer | I4: Dayne H | P4: 6mm Eye-Eye | R4: 8mm | S4: 12mm@250mm
B5: Customer Name | D5: Mackay | I5: David M | P5: 8mm Hook-Hook | R5: 10mm | S5: 16mm Welded@200mm
C6: Job Number | I6: Brian V | P6: 8mm Eye-Eye | R6: 12mm | S6: 16mm Welded@250mm
B7: Address: | C7: Street: | I7: Matt | P7: 10mm Hook-Hook | S7: 16mm Welded@300mm
C8: Suburb: | P8: 10mm Eye-Eye | S8: 16mm Welded@400mm
C9: State: | D9: - | E9: Postcode: | F9: - | P9: 12mm Hook-Hook | S9: 20mm Welded@200mm
B10: Email: | D10: - | L10: Take offs | P10: 12mm Eye-Eye | S10: 20mm Welded@250mm
C11: Email Server: | D11: - | K11: D Shackles | L11: Turn Buckles | M11: Toggles | N11: Lacing | P11: 16mm Hook-Hook | S11: 20mm Welded@300mm
C12: Email Authentication: | P12: 16mm Eye-Eye | S12: 20mm Welded@400mm
B13: Phone Number: | D13: -
B14: Fax Number: | D14: - | I14: Terminated | K14: 80 | L14: 400 | M14: 150 | N14: 150
C15: Version: | D15: 1.8 | I15: Continuous | K15: 100 | L15: 500 | M15: 175 | N15: 200
B16: Shade Sail Setup | I16: Inline | K16: 120 | L16: 600 | M16: 200 | N16: 300
B17: Take off Lengths | M17: 250 | N17: 400
B18: Take off Ropes/Lacing: | D18: 150 | N18: 500
B19: Size T Buckle: | D19: 8mm Hook-Hook
B20: Size D Shackle: | D20: 8mm
B21: Size Toggle:
B22: Take Off for Toggles:
B23: Take Off for T Buckle: | D23: 400 | H23: T8=400mm | I23: T10=500mm | J23: T12=600mm
B24: Take Off for D.S.: | D24: 80 | K24: Cable Size | L24: Offset %
B25: Cable Style: | D25: Continuous | I25: Turn Buckles: | K25: -
B26: Delivery Option: | D26: Pickup | I26: Bottle Screws: | K26: 3mm | L26: 0.02
B27: Fold Direction: | D27: Underside | K27: 4mm | L27: 0.03
B28: Thread: | D28: PTFE | I28: Delivery | K28: 5mm | L28: 0.04
B29: Cable Size: | D29: 4mm | I29: Pickup | K29: 6mm | L29: 0.05
B30: Corner Fittings: | D30: Small Pro-Rig | K30: 8mm | L30: 0.06
B31: Offset %: | D31: 0.05 | I31: Underside | K31: 10mm | L31: 0.07
I32: Topside | L32: 0.08
L33: 0.09
L34: 0.1

Sheet Main
C2: DATE: | F2: =TODAY() -> 46135 | K2: DELIVERY | L2: =IF(Details!D26="PICKUP","PICK UP",Details!D7) -> PICK UP
C3: COMPANY: | F3: =Details!D5 -> Mackay | K3: ADDRESS | L3: =IF(Details!D26="PICKUP","-",CONCATENATE(Details!D8," ",Details!D9," ",Details!F9)) -> -
C4: REF: | K4: PH/FAX: | L4: =Details!D13 -> - | M4: =Details!D14 -> -
C6: BRAND: | F6: Z 16
C7: COLOUR: | F7: CHARCOAL
C9: Number of fixing points | G9: 6
N10: TAKE OFF LENGTH | O10: REVERSE CURVE
C11: ='shade check'!C9 -> POINT-POINT | F11: ='shade check'!F9 -> OFFSET | G11: DIST | H11: Exit Point | J11: POST HEIGHT | L11: ='shade check'!K9 -> FIXED TO | M11: ='shade check'!L9 -> FIXING
C13: ='shade check'!C11 -> A-B | D13: 4370 | F13: =Details!$D$31 -> 0.05 | G13: =ROUND('shade check'!AZ23,-1) -> 220 | H13: - | I13: ='shade check'!H11 -> A | N13: =VLOOKUP(Main!M13,Main!$P$13:$Q$18,2,FALSE) -> #N/A | O13: - | P13: TURN BUCKLE | Q13: =Details!D23 -> 400
C14: ='shade check'!C12 -> B-C | D14: 4340 | F14: =Details!$D$31 -> 0.05 | G14: =ROUND('shade check'!AZ24,-1) -> 220 | H14: - | I14: ='shade check'!H12 -> B | N14: =VLOOKUP(Main!M14,Main!$P$13:$Q$18,2,FALSE) -> #N/A | O14: - | P14: D SHACKLE | Q14: =Details!D24 -> 80
C15: ='shade check'!C13 -> C-D | D15: 7160 | F15: =Details!$D$31 -> 0.05 | G15: =ROUND('shade check'!AZ25,-1) -> 360 | H15: - | I15: ='shade check'!H13 -> C | N15: =VLOOKUP(Main!M15,Main!$P$13:$Q$18,2,FALSE) -> #N/A | O15: - | P15: TOGGLE | Q15: =Details!D22 -> 0
C16: ='shade check'!C14 -> D-E | D16: 3490 | F16: =Details!$D$31 -> 0.05 | G16: =ROUND('shade check'!AZ26,-1) -> 170 | H16: - | I16: ='shade check'!H14 -> D | N16: =VLOOKUP(Main!M16,Main!$P$13:$Q$18,2,FALSE) -> #N/A | O16: - | P16: CABLE TRACE | Q16: 0
C17: ='shade check'!C15 -> E-F | D17: 2600 | F17: =Details!$D$31 -> 0.05 | G17: =ROUND('shade check'!AZ27,-1) -> 130 | I17: ='shade check'!H15 -> E | N17: =VLOOKUP(Main!M17,Main!$P$13:$Q$18,2,FALSE) -> #N/A | O17: - | P17: SAIL TRACK
C18: ='shade check'!C16 -> F-A | D18: 7480 | F18: =Details!$D$31 -> 0.05 | G18: =ROUND('shade check'!AZ28,-1) -> 140 | H18: - | I18: ='shade check'!H16 -> F | L18: - | M18: - | N18: =VLOOKUP(Main!M18,Main!$P$13:$Q$18,2,FALSE) -> #N/A | O18: - | P18: LACING | Q18: =Details!D18 -> 150
C19: ='shade check'!C17 | D19: - | F19: =Details!$D$31 -> 0.05 | G19: =ROUND('shade check'!AZ29,-1) -> 0 | H19: - | I19: ='shade check'!H17 | J19: 0 | L19: - | M19: - | N19: =VLOOKUP(Main!M19,Main!$P$13:$Q$18,2,FALSE) -> #N/A | O19: -
C20: ='shade check'!C18 | D20: - | F20: =Details!$D$31 -> 0.05 | G20: =ROUND('shade check'!AZ30,-1) -> 0 | H20: - | I20: ='shade check'!H18 | J20: 0 | L20: - | M20: - | N20: =VLOOKUP(Main!M20,Main!$P$13:$Q$18,2,FALSE) -> #N/A | O20: -
C22: ='shade check'!C23 -> DIAGONAL POINT TO POINT
C24: ='shade check'!C25 -> A-C | D24: 7750
C25: ='shade check'!C26 -> A-D | D25: 10420
C26: ='shade check'!C27 -> A-E | D26: 8280
C27: ='shade check'!C28 -> B-D | D27: 8300
C28: ='shade check'!C29 -> B-E | D28: 7390
C29: ='shade check'!C30 -> B-F | D29: 8020
C30: ='shade check'!C31 -> C-E | D30: 8080
C31: ='shade check'!C32 -> C-F | D31: 9570
C32: ='shade check'!C33 -> D-F | D32: 5990
C33: ='shade check'!C34 | D33: -
C34: ='shade check'!C35 | D34: -
C35: ='shade check'!C36 | D35: -
C36: ='shade check'!C37 | D36: -
C37: ='shade check'!C38 | D37: -
C38: ='shade check'!C39 | D38: -
C39: ='shade check'!C40 | D39: -
C40: ='shade check'!C41 | D40: -
C41: ='shade check'!C42 | D41: -
C42: ='shade check'!C43 | D42: -
C43: ='shade check'!C44 | D43: -
D45: Version: | F45: =Details!D15 -> 1.8
Z50: 6mm Triangle | AB50: ROOF
Z51: 6mm D-ring | AB51: WALL | AH51: Welded
...

Sheet Print
C2: DATE: | F2: =TODAY() -> 46135 | L2: Phone | M2: 0466 256 405/ 0466 069 614
C3: Customer | F3: =Details!D5 -> Mackay
C4: Job No | F4: =Details!D6 -> 0 | L4: Email | M4: jayson@sunsafeshadesails.com.au
D5: Installer: | F5: =Details!D4 -> 0
C6: BRAND: | F6: =Main!F6 -> Z 16 | L6: Thread: | N6: =Details!D28 -> PTFE
C7: COLOUR: | F7: =Main!F7 -> CHARCOAL | L7: =Details!B27 -> Fold Direction: | N7: =Details!D27 -> Underside
L8: =Details!B30 -> Corner Fittings: | N8: =Details!D30 -> Small Pro-Rig
C9: Number of fixing points | G9: =Main!G9 -> 6 | L9: Cable Size: | N9: =Details!D29 -> 4mm
L10: Cable Style: | N10: =Details!D25 -> Continuous
F11: ACT. SAIL | O11: TAKE OFF LENGTH | P11: REVERSE CURVE
C12: ='shade check'!C9 -> POINT-POINT | G12: ='shade check'!F9 -> OFFSET | H12: DIST | I12: Exit point | K12: POST HEIGHT | M12: ='shade check'!K9 -> FIXED TO | N12: ='shade check'!L9 -> FIXING
C14: ='shade check'!C11 -> A-B | D14: =Main!D13 -> 4370 | E14: =Main!E13 -> 0 | F14: ='shade check'!BB23 -> 0 | G14: =Main!F13 -> 0.05 | H14: =ROUND('shade check'!AZ23,-1) -> 220 | I14: =Main!H13 -> - | K14: ='shade check'!H11 -> A | L14: =Main!J13 -> 0 | M14: =Main!L13 -> 0 | N14: =Main!M13 -> 0 | O14: =Main!N13 -> #N/A | P14: =Main!O13 -> -
C15: ='shade check'!C12 -> B-C | D15: =Main!D14 -> 4340 | E15: =Main!E14 -> 0 | F15: ='shade check'!BB24 -> 0 | G15: =Main!F14 -> 0.05 | H15: =ROUND('shade check'!AZ24,-1) -> 220 | I15: =Main!H14 -> - | K15: ='shade check'!H12 -> B | L15: =Main!J14 -> 0 | M15: =Main!L14 -> 0 | N15: =Main!M14 -> 0 | O15: =Main!N14 -> #N/A | P15: =Main!O14 -> -
C16: ='shade check'!C13 -> C-D | D16: =Main!D15 -> 7160 | E16: =Main!E15 -> 0 | F16: ='shade check'!BB25 -> 0 | G16: =Main!F15 -> 0.05 | H16: =ROUND('shade check'!AZ25,-1) -> 360 | I16: =Main!H15 -> - | K16: ='shade check'!H13 -> C | L16: =Main!J15 -> 0 | M16: =Main!L15 -> 0 | N16: =Main!M15 -> 0 | O16: =Main!N15 -> #N/A | P16: =Main!O15 -> -
C17: ='shade check'!C14 -> D-E | D17: =Main!D16 -> 3490 | E17: =Main!E16 -> 0 | F17: ='shade check'!BB26 -> 0 | G17: =Main!F16 -> 0.05 | H17: =ROUND('shade check'!AZ26,-1) -> 170 | I17: =Main!H16 -> - | K17: ='shade check'!H14 -> D | L17: =Main!J16 -> 0 | M17: =Main!L16 -> 0 | N17: =Main!M16 -> 0 | O17: =Main!N16 -> #N/A | P17: =Main!O16 -> -
C18: ='shade check'!C15 -> E-F | D18: =Main!D17 -> 2600 | E18: =Main!E17 -> 0 | F18: ='shade check'!BB27 -> 0 | G18: =Main!F17 -> 0.05 | H18: =ROUND('shade check'!AZ27,-1) -> 130 | I18: =Main!H17 -> 0 | K18: ='shade check'!H15 -> E | L18: =Main!J17 -> 0 | M18: =Main!L17 -> 0 | N18: =Main!M17 -> 0 | O18: =Main!N17 -> #N/A | P18: =Main!O17 -> -
C19: ='shade check'!C16 -> F-A | D19: =Main!D18 -> 7480 | E19: =Main!E18 -> 0 | F19: ='shade check'!BB28 -> 0 | G19: =Main!F18 -> 0.05 | H19: =ROUND('shade check'!AZ28,-1) -> 140 | I19: =Main!H18 -> - | K19: ='shade check'!H16 -> F | L19: =Main!J18 -> 0 | M19: =Main!L18 -> - | N19: =Main!M18 -> - | O19: =Main!N18 -> #N/A | P19: =Main!O18 -> -
C20: ='shade check'!C17 | D20: =Main!D19 -> - | E20: =Main!E19 -> 0 | F20: ='shade check'!BB29 -> 0 | G20: =Main!F19 -> 0.05 | H20: =ROUND('shade check'!AZ29,-1) -> 0 | I20: =Main!H19 -> - | K20: ='shade check'!H17 | L20: =Main!J19 -> 0 | M20: =Main!L19 -> - | N20: =Main!M19 -> - | O20: =Main!N19 -> #N/A | P20: =Main!O19 -> -
C21: ='shade check'!C18 | D21: =Main!D20 -> - | E21: =Main!E20 -> 0 | F21: ='shade check'!BB30 -> 0 | G21: =Main!F20 -> 0.05 | H21: =ROUND('shade check'!AZ30,-1) -> 0 | I21: =Main!H20 -> - | K21: ='shade check'!H18 | L21: =Main!J20 -> 0 | M21: =Main!L20 -> - | N21: =Main!M20 -> - | O21: =Main!N20 -> #N/A | P21: =Main!O20 -> -
D22: =SUM(D14:D21)+2 -> 29442 | F22: Cable Length | O22: =Details!B19 -> Size T Buckle: | P22: T10
C23: ='shade check'!C20 -> - ERROR - REMEASURE | G23: ='shade check'!G20 -> Error | H23: Sail Manufacturer | O23: =Details!B20 -> Size D Shackle: | P23: SH8
G24: ='shade check'!G21 -> 0.1043533 | O24: =Details!B21 -> Size Toggle:
C26: ='shade check'!C23 -> DIAGONAL POINT TO POINT | H26: Installer
B28: ='shade check'!B25 -> 1 | C28: ='shade check'!C25 -> A-C | D28: =Main!D24 -> 7750
B29: ='shade check'!B26 -> 2 | C29: ='shade check'!C26 -> A-D | D29: =Main!D25 -> 10420
B30: ='shade check'!B27 -> 3 | C30: ='shade check'!C27 -> A-E | D30: =Main!D26 -> 8280
B31: ='shade check'!B28 -> 4 | C31: ='shade check'!C28 -> B-D | D31: =Main!D27 -> 8300
B32: ='shade check'!B29 -> 5 | C32: ='shade check'!C29 -> B-E | D32: =Main!D28 -> 7390
B33: ='shade check'!B30 -> 6 | C33: ='shade check'!C30 -> B-F | D33: =Main!D29 -> 8020
B34: ='shade check'!B31 -> 7 | C34: ='shade check'!C31 -> C-E | D34: =Main!D30 -> 8080
B35: ='shade check'!B32 -> 8 | C35: ='shade check'!C32 -> C-F | D35: =Main!D31 -> 9570
B36: ='shade check'!B33 -> 9 | C36: ='shade check'!C33 -> D-F | D36: =Main!D32 -> 5990
B37: ='shade check'!B34 -> 10 | C37: ='shade check'!C34 | D37: =Main!D33 -> -
B38: ='shade check'!B35 -> 11 | C38: ='shade check'!C35 | D38: =Main!D34 -> -
B39: ='shade check'!B36 -> 12 | C39: ='shade check'!C36 | D39: =Main!D35 -> -
... B47: ='shade check'!B44 -> 20 | C47: ='shade check'!C44 | D47: =Main!D43 -> -
AK48: Cable Style
C49: ='shade check'!C46 -> 1 | D49: ='shade check'!D46 -> 2
U51: 1 | V51: RAINBOW Z16 | W51: BLACK | AA51: 6mm Triangle | AC51: ROOF | AD51: LACING | AE51: =Details!D18 -> 150 | AK51: Terminated
U52: 2 | W52: RAINFOREST | AA52: 6mm D-ring | AC52: WALL | AD52: =IF(LEFT(Details!B23,1)="T","TURN BUCKLE","BOTTLE SCREW") -> TURN BUCKLE | AE52: =Details!D23 -> 400 | AK52: Contiuous
...

Sheet SaveControl
B1: NAME | C1: Value | D1: Default
A2: DETAILS | B2: =Details!B5 -> Customer Name | C2: =Details!D5 -> Mackay | D2: -
A3: DETAILS | B3: =Details!C7 -> Street: | C3: =Details!D7 -> 0 | D3: -
A4: DETAILS | B4: =Details!C8 -> Suburb: | C4: =Details!D8 -> 0 | D4: -
A5: DETAILS | B5: =Details!C9 -> State: | C5: =Details!D9 -> - | D5: -
A6: DETAILS | B6: =Details!E9 -> Postcode: | C6: =Details!F9 -> - | D6: -
A7: DETAILS | B7: =Details!B13 -> Phone Number: | C7: =Details!D13 -> - | D7: -
A8: DETAILS | B8: =Details!B14 -> Fax Number: | C8: =Details!D14 -> - | D8: -
A9: DETAILS | B9: =Details!B10 -> Email: | C9: =Details!D10 -> - | D9: -
A10: DETAILS | B10: =Details!B18 -> Take off Ropes/Lacing: | C10: =Details!D18 -> 150 | D10: 130
A11: DETAILS | B11: =Details!B23 -> Take Off for T Buckle: | C11: =Details!D23 -> 400 | D11: 210
A12: DETAILS | B12: =Details!B24 -> Take Off for D.S.: | C12: =Details!D24 -> 80 | D12: 32
A13: DETAILS | B13: =Details!B25 -> Cable Style: | C13: =Details!D25 -> Continuous | D13: 0
A14: DETAILS | B14: =Details!B26 -> Delivery Option: | C14: =Details!D26 -> Pickup | D14: Delivery
A15: DETAILS | B15: Fold Direction: | C15: =Details!D27 -> Underside | D15: -
A16: DETAILS | B16: =Details!C11 -> Email Server: | C16: =Details!D11 -> - | D16: -
A17: DETAILS | B17: =Details!C12 -> Email Authentication: | C17: =Details!D12 -> 0
A18: MAIN | B18: =Main!C2 -> DATE: | C18: =Main!F2 -> 46135 | D18: =TODAY() -> 46135
A19: MAIN | B19: =Main!C4 -> REF: | C19: =Main!F4 -> 0 | D19: -
A20: MAIN | B20: =Main!C6 -> BRAND: | C20: =Main!F6 -> Z 16 | D20: 0
A21: MAIN | B21: =Main!C7 -> COLOUR: | C21: =Main!F7 -> CHARCOAL
A22: MAIN | B22: =Main!C9 -> Number of fixing points | C22: =Main!G9 -> 6 | D22: 4
A23: MAIN | B23: =Main!K8 -> 0 | C23: =Main!M8 -> 0 | D23: =Details!D25 -> Continuous
A24: MAIN | B24: =Main!K6 -> 0 | C24: =Main!M6 -> 0 | D24: NO
A25: MAIN | B25: Edge Type | C25: =Main!M9 -> 0
A26: MAIN | B26: =Main!C13 -> A-B | C26: =Main!D13 -> 4370 | D26: -
A27: MAIN | B27: =Main!C14 -> B-C | C27: =Main!D14 -> 4340 | D27: -
A28: MAIN | B28: =Main!C15 -> C-D | C28: =Main!D15 -> 7160 | D28: -
A29: MAIN | B29: =Main!C16 -> D-E | C29: =Main!D16 -> 3490 | D29: -
A30: MAIN | B30: =Main!C17 -> E-F | C30: =Main!D17 -> 2600 | D30: -
A31: MAIN | B31: =Main!C18 -> F-A | C31: =Main!D18 -> 7480 | D31: -
A32: MAIN | B32: =Main!C19 | C32: =Main!D19 -> - | D32: -
A33: MAIN | B33: =Main!C20 | C33: =Main!D20 -> - | D33: -
A34: MAIN | B34: =Main!I13 -> A | C34: =Main!J13 -> 0 | D34: -
A35: MAIN | B35: =Main!I14 -> B | C35: =Main!J14 -> 0 | D35: -
A36: MAIN | B36: =Main!I15 -> C | C36: =Main!J15 -> 0 | D36: -
A37: MAIN | B37: =Main!I16 -> D | C37: =Main!J16 -> 0 | D37: -
A38: MAIN | B38: =Main!I17 -> E | C38: =Main!J17 -> 0 | D38: -
A39: MAIN | B39: =Main!I18 -> F | C39: =Main!J18 -> 0 | D39: -
A40: MAIN | B40: =Main!I19 | C40: =Main!J19 -> 0 | D40: -
...

Sheet shade check
C3: CUSTOMER: | F3: JUSTIN
C4: REF: | F4: 56 magnesium drive PH 38036000
C5: COLOUR: | F5: =Print!F6 -> Z 16
C7: Number of Posts: | G7: =Print!G9 -> 6 | AT7: =IF(G7=3,(Z12*Z12),(AT8*AT8)) -> 64320400 | AW7: 0 | AX7: 0
AT8: =VLOOKUP(CONCATENATE("B-",HLOOKUP("A",H11:H18,G7,FALSE)),C25:Y44,23,FALSE) -> 8020 | AW8: 0.04 | AX8: 3.145
C9: POINT-POINT | F9: OFFSET | G9: TAG | H9: POST HEIGHT | K9: FIXED TO | L9: FIXING | M9: T/ LENGTH | O9: 180º | Z9: 0 REF | AB9: DIFFER BETWEEN POSTS | AI9: Trace X | AJ9: Trace Y | AK9: T Length | AL9: T angle | AO9: new X | AP9: new Y | AW9: 0.05 | AX9: 2.525
Q10: A | R10: B | S10: C | T10: D | U10: E | V10: F | W10: G | X10: H | AE10: ANGLE | AG10: 0 | AH10: 0 | AM10: 0 | AN10: 0 | AO10: 0 | AP10: 0 | AR10: =(G7-2)*180 -> 720 | AW10: 0.06 | AX10: 2.1135 | AZ10: X | BA10: Y | BB10: DIST | BC10: MID X | BD10: MID Y | BE10: ANGLE | BG10: CENTRE
C11: A-B | D11: =Print!D14 -> 4370 | E11: =Print!E14 -> 0 | F11: =Print!G14 -> 0.05 | G11: =Print!I14 -> - | H11: A | I11: =Print!L14 -> 0 | K11: =Print!M14 -> 0 | L11: =Print!N14 -> 0 | M11: =Print!O14 -> #N/A | O11: =IF(LEFT(Print!P14,3)="180",180,0) -> 0 | Q11: =IF(OR(LEFT(C11,1)="A",RIGHT(C11,1)="A"),"A","") -> A | R11: =IF(OR(LEFT(C11,1)="B",RIGHT(C11,1)="B"),"B","") -> B | S11: =IF(OR(LEFT(C11,1)="C",RIGHT(C11,1)="C"),"C","") | T11: =IF(OR(LEFT(C11,1)="D",RIGHT(C11,1)="D"),"D","") | U11: =IF(OR(LEFT(C11,1)="E",RIGHT(C11,1)="E"),"E","") | V11: =IF(OR(LEFT(C11,1)="F",RIGHT(C11,1)="F"),"F","") | W11: =IF(OR(LEFT(C11,1)="G",RIGHT(C11,1)="G"),"G","") | X11: =IF(OR(LEFT(C11,1)="H",RIGHT(C11,1)="H"),"H","") | Z11: =SQRT((D11*D11)-(AB11*AB11)) -> 4370 | AB11: =I11-I12 -> 0 | AD11: A | AE11: =IF(O11=180,PI(),IF(Main!O13="R",PI()-ACOS(((VLOOKUP("A",Q12:Z18,10,FALSE)*VLOOKUP("A",Q12:Z18,10,FALSE))+(Z11*Z11)-AT7)/(2*Z11*VLOOKUP("A",Q12:Z18,10,FALSE)))+PI(),ACOS(((VLOOKUP("A",Q12:Z18,10,FALSE)*VLOOKUP("A",Q12:Z18,10,FALSE))+(Z11*Z11)-AT7)/(2*Z11*VLOOKUP("A",Q12:Z18,10,FALSE))))) -> 1.4059689 | AF11: =AE11*180/PI() -> 80.556084 | AG11: =Z11 -> 4370 | AH11: =0 -> 0 | AI11: =IF(ISERROR(AK11*COS(AL11)),0,AK11*COS(AL11)) -> 0 | AJ11: =IF(ISERROR(AK11*SIN(AL11)),0,AK11*SIN(AL11)) -> 0 | AK11: =M11 -> #N/A | AL11: =2*PI()-AE11/2 -> 5.5802009 | AM11: =AI11 -> 0 | AN11: =AJ11 -> 0 | AO11: =AG10+AI11 -> 0 | AP11: =(AH10+AJ11) -> 0 | AQ11: =AL11*180/PI() -> 319.72196 | AR11: =SUM(AF11:AF18) -> 644.86563 | AS11: =ABS(AR10-AR11) -> 75.134374 | AT11: =AM11 -> 0 | AU11: =AN11 -> 0 | AW11: 0.07 | AX11: 1.8205 | AZ11: =AM11 -> 0 | BA11: =AN11 -> 0 | BG11: ANGLE | BI11: X | BJ11: Y | BK11: RADIUS | BL11: DIRECTION | BM11: A | BN11: B
C12: B-C | D12: =Print!D15 -> 4340 | E12: =Print!E15 -> 0 | F12: =Print!G15 -> 0.05 | G12: =Print!I15 -> - | H12: B | I12: =Print!L15 -> 0 | K12: =Print!M15 -> 0 | L12: =Print!N15 -> 0 | M12: =Print!O15 -> #N/A | O12: =IF(LEFT(Print!P15,3)="180",180,0) -> 0 | Q12: =IF(OR(LEFT(C12,1)="A",RIGHT(C12,1)="A"),"A","") | R12: =IF(OR(LEFT(C12,1)="B",RIGHT(C12,1)="B"),"B","") -> B | S12: =IF(OR(LEFT(C12,1)="C",RIGHT(C12,1)="C"),"C","") -> C | T12: =IF(OR(LEFT(C12,1)="D",RIGHT(C12,1)="D"),"D","") | U12: =IF(OR(LEFT(C12,1)="E",RIGHT(C12,1)="E"),"E","") | V12: =IF(OR(LEFT(C12,1)="F",RIGHT(C12,1)="F"),"F","") | W12: =IF(OR(LEFT(C12,1)="G",RIGHT(C12,1)="G"),"G","") | X12: =IF(OR(LEFT(C12,1)="H",RIGHT(C12,1)="H"),"H","") | Z12: =SQRT((D12*D12)-(AB12*AB12)) -> 4340 | AB12: =I12-I13 -> 0 | AD12: B | AE12: =IF(O12=180,PI(),IF(Main!O14="R",PI()-IF(G7=3,ACOS(((Z12*Z12)+(Z11*Z11)-(Z13*Z13))/(2*Z11*Z12)),ACOS(((Z12*Z12)+(Z11*Z11)-(Y25*Y25))/(2*Z11*Z12)))+PI(),IF(G7=3,ACOS(((Z12*Z12)+(Z11*Z11)-(Z13*Z13))/(2*Z11*Z12)),ACOS(((Z12*Z12)+(Z11*Z11)-(Y25*Y25))/(2*Z11*Z12))))) -> 2.1937279 | AF12: =AE12*180/PI() -> 125.69135 | AG12: =Z11+(Z12*-COS(AE12)) -> 6902.0366 | AH12: =-Z12*SIN(AE12) -> -3524.8249 | AI12: =IF(ISERROR(AK12*COS(AL12)),0,AK12*COS(AL12)) -> 0 | AJ12: =IF(ISERROR(AK12*SIN(AL12)),0,AK12*SIN(AL12)) -> 0 | AK12: =M12 -> #N/A | AL12: =AE12/2+PI() -> 4.2384566 | AM12: =AG11+AI12 -> 4370 | AN12: =AJ12 -> 0 | AO12: =AG11+AI12 -> 4370 | AP12: =(AH11+AJ12) -> 0 | AQ12: =AL12*180/PI() -> 242.84567 | AT12: =AM12 -> 4370 | AU12: =AN12 -> 0 | AW12: 0.08 | AX12: 1.6025 | AY12: A | AZ12: =AM12 -> 4370 | BA12: =AN12 -> 0 | BB12: =SQRT(((AZ12-AZ11)*(AZ12-AZ11))+((BA12-BA11)*(BA12-BA11))) -> 4370 | BC12: =(AZ12-AZ11)/2+AZ11 -> 2185 | BD12: =(BA12-BA11)/2+BA11 -> 0 | BE12: =IF(AND(AZ12-AZ11>0,BA12-BA11>0),ATAN((BA12-BA11)/(AZ12-AZ11)),IF(AND(AZ12-AZ11<0,BA12-BA11>0),PI()+ATAN((BA12-BA11)/(AZ12-AZ11)),IF(AND(AZ12-AZ11<0,BA12-BA11<0),PI()+ATAN((BA12-BA11)/(AZ12-AZ11)),2*PI()+ATAN((BA12-BA11)/(AZ12-AZ11))))) -> 6.2831853 | BF12: =BE12*180/PI() -> 360 | BG12: =BE12+PI()/2 -> 7.8539816 | BH12: =BG12*180/PI() -> 450 | BI12: =COS(BG12)*(BK12-(BB12*F11))+BC12 -> 2185 | BJ12: =SIN(BG12)*(BK12-(BB12*F11))+BD12 -> 10815.75 | BK12: =BB12*VLOOKUP(F11,$AW$7:$AX$12,2,FALSE) -> 11034.25 | BL12: =IF(ABS(AZ12-AZ11)>ABS(BA12-BA11),"X","Y") -> X | BM12: =IF(BL12="Y",BI12,BJ12) -> 10815.75 | BN12: =IF(BL12="Y",BJ12,BI12) -> 2185
C13: =IF(G7=3,"C-A","C-D") -> C-D | D13: =Print!D16 -> 7160 | E13: =Print!E16 -> 0 | F13: =Print!G16 -> 0.05 | G13: =Print!I16 -> - | H13: C | I13: =Print!L16 -> 0 | K13: =Print!M16 -> 0 | L13: =Print!N16 -> 0 | M13: =Print!O16 -> #N/A | O13: =IF(LEFT(Print!P16,3)="180",180,0) -> 0 | Q13: =IF(OR(LEFT(C13,1)="A",RIGHT(C13,1)="A"),"A","") | R13: =IF(OR(LEFT(C13,1)="B",RIGHT(C13,1)="B"),"B","") | S13: =IF(OR(LEFT(C13,1)="C",RIGHT(C13,1)="C"),"C","") -> C | T13: =IF(OR(LEFT(C13,1)="D",RIGHT(C13,1)="D"),"D","") -> D | U13: =IF(OR(LEFT(C13,1)="E",RIGHT(C13,1)="E"),"E","") | V13: =IF(OR(LEFT(C13,1)="F",RIGHT(C13,1)="F"),"F","") | W13: =IF(OR(LEFT(C13,1)="G",RIGHT(C13,1)="G"),"G","") | X13: =IF(OR(LEFT(C13,1)="H",RIGHT(C13,1)="H"),"H","") | Z13: =SQRT((D13*D13)-(AB13*AB13)) -> 7160 | AB13: =VLOOKUP(LEFT(C13,1),HEIGHT,2,FALSE)-VLOOKUP(RIGHT(C13,1),HEIGHT,2,FALSE) -> 0 | AD13: C | AE13: =IF(O13=180,PI(),IF(Main!O15="R",PI()-IF(G7=3,ACOS(((Z13*Z13)+(Z12*Z12)-(Z11*Z11))/(2*Z12*Z13)),ACOS(((Z13*Z13)+(Z12*Z12)-(VLOOKUP("B-D",C25:Y44,23,FALSE)*VLOOKUP("B-D",C25:Y44,23,FALSE)))/(2*Z12*Z13)))+PI(),IF(G7=3,ACOS(((Z13*Z13)+(Z12*Z12)-(Z11*Z11))/(2*Z12*Z13)),ACOS(((Z13*Z13)+(Z12*Z12)-(VLOOKUP("B-D",C25:Y44,23,FALSE)*VLOOKUP("B-D",C25:Y44,23,FALSE)))/(2*Z12*Z13))))) -> 1.5513064 | AF13: =AE13*180/PI() -> 88.883308 | AG13: =IF(G7<4,0,AG12-(Z13*COS(PI()-AE12-AE13))) -> 1006.5824 | AH13: =IF(G7<4,0,AH12+(Z13*SIN(PI()-AE12-AE13))) -> -7587.9788 | AI13: =IF(ISERROR(AK13*COS(AL13)),0,AK13*COS(AL13)) -> 0 | AJ13: =IF(ISERROR(AK13*SIN(AL13)),0,AK13*SIN(AL13)) -> 0 | AK13: =M13 -> #N/A | AL13: =AE12+PI()-(PI()-AE13)-AE13/2 -> 2.9693811 | AM13: =AG11 -> 4370 | AN13: =AH11 -> 0 | AO13: =AG11 -> 4370 | AP13: =AH11 -> 0 | AQ13: =AL13*180/PI() -> 170.133 | AS13: =IF(AS11/AR10>(0.0085-(0.001*G7)),"ERROR","CORRECT") -> ERROR | AT13: =AM15 -> 6902.0366 | AU13: =AN15 -> -3524.8249 | AY13: B | AZ13: =AM15 -> 6902.0366 | BA13: =AN15 -> -3524.8249 | BB13: =SQRT(((AZ13-AZ12)*(AZ13-AZ12))+((BA13-BA12)*(BA13-BA12))) -> 4340 | BC13: =(AZ13-AZ12)/2+AZ12 -> 5636.0183 | BD13: =(BA13-BA12)/2+BA12 -> -1762.4125 | BE13: =IF(AND(AZ13-AZ12>0,BA13-BA12>0),ATAN((BA13-BA12)/(AZ13-AZ12)),IF(AND(AZ13-AZ12<0,BA13-BA12>0),PI()+ATAN((BA13-BA12)/(AZ13-AZ12)),IF(AND(AZ13-AZ12<0,BA13-BA12<0),PI()+ATAN((BA13-BA12)/(AZ13-AZ12)),2*PI()+ATAN((BA13-BA12)/(AZ13-AZ12))))) -> 5.3353205 | BF13: =BE13*180/PI() -> 305.69135 | BG13: =BE13+PI()/2 -> 6.9061168 | BH13: =BG13*180/PI() -> 395.69135 | BI13: =COS(BG13)*(BK13-(BB13*F12))+BC13 -> 14359.96 | BJ13: =SIN(BG13)*(BK13-(BB13*F12))+BD13 -> 4504.3782 | BK13: =BB13*VLOOKUP(F12,$AW$7:$AX$12,2,FALSE) -> 10958.5 | BL13: =IF(ABS(AZ13-AZ12)>ABS(BA13-BA12),"X","Y") -> Y | BM13: =IF(BL13="Y",BI13,BJ13) -> 14359.96 | BN13: =IF(BL13="Y",BJ13,BI13) -> 4504.3782
C14: =IF(G7=4,"D-A",IF(G7>4,"D-E","")) -> D-E | D14: =Print!D17 -> 3490 | E14: =Print!E17 -> 0 | F14: =Print!G17 -> 0.05 | G14: =Print!I17 -> - | H14: =IF(G7>=4,"D","") -> D | I14: =Print!L17 -> 0 | K14: =Print!M17 -> 0 | L14: =Print!N17 -> 0 | M14: =Print!O17 -> #N/A | O14: =IF(LEFT(Print!P17,3)="180",180,0) -> 0 | Q14: =IF(OR(LEFT(C14,1)="A",RIGHT(C14,1)="A"),"A","") | R14: =IF(OR(LEFT(C14,1)="B",RIGHT(C14,1)="B"),"B","") | S14: =IF(OR(LEFT(C14,1)="C",RIGHT(C14,1)="C"),"C","") | T14: =IF(OR(LEFT(C14,1)="D",RIGHT(C14,1)="D"),"D","") -> D | U14: =IF(OR(LEFT(C14,1)="E",RIGHT(C14,1)="E"),"E","") -> E | V14: =IF(OR(LEFT(C14,1)="F",RIGHT(C14,1)="F"),"F","") | W14: =IF(OR(LEFT(C14,1)="G",RIGHT(C14,1)="G"),"G","") | X14: =IF(OR(LEFT(C14,1)="H",RIGHT(C14,1)="H"),"H","") | Z14: =SQRT((D14*D14)-(AB14*AB14)) -> 3490 | AB14: =VLOOKUP(LEFT(C14,1),HEIGHT,2,FALSE)-VLOOKUP(RIGHT(C14,1),HEIGHT,2,FALSE) -> 0 | AD14: D | AE14: =IF(O14=180,PI(),IF(Main!O16="R",PI()-IF(G7=4,ACOS(((Z14*Z14)+(Z13*Z13)-(Y25*Y25))/(2*Z13*Z14)),ACOS(((Z14*Z14)+(Z13*Z13)-(VLOOKUP("C-E",C25:Y44,23,FALSE)*VLOOKUP("C-E",C25:Y44,23,FALSE)))/(2*Z13*Z14)))+PI(),IF(G7=4,ACOS(((Z14*Z14)+(Z13*Z13)-(Y25*Y25))/(2*Z13*Z14)),ACOS(((Z14*Z14)+(Z13*Z13)-(VLOOKUP("C-E",C25:Y44,23,FALSE)*VLOOKUP("C-E",C25:Y44,23,FALSE)))/(2*Z13*Z14))))) -> 1.6076357 | AF14: =AE14*180/PI() -> 92.110743 | AG14: =IF(G7<5,0,AG13-(Z14*COS(PI()-AE14+(PI()-AE12-AE13)))) -> -1078.4163 | AH14: =IF(G7<5,0,AH13+(Z14*SIN(PI()-AE14+(PI()-AE12-AE13)))) -> -4789.2504 | AI14: =IF(ISERROR(AK14*COS(AL14)),0,AK14*COS(AL14)) -> 0 | AJ14: =IF(ISERROR(AK14*SIN(AL14)),0,AK14*SIN(AL14)) -> 0 | AK14: =M14 -> #N/A | AL14: =PI()+AE12-(PI()-AE13)-(PI()-AE14)-AE14/2 -> 1.4072595 | AM14: =AM12 -> 4370 | AN14: =AN12 -> 0 | AO14: =AO12 -> 4370 | AP14: =AP12 -> 0 | AQ14: =AL14*180/PI() -> 80.630028 | AT14: =AM18 -> 1006.5824 | AU14: =AN18 -> -7587.9788 | AY14: C | AZ14: =AM18 -> 1006.5824 | BA14: =AN18 -> -7587.9788 | BB14: =SQRT(((AZ14-AZ13)*(AZ14-AZ13))+((BA14-BA13)*(BA14-BA13))) -> 7160 | BC14: =(AZ14-AZ13)/2+AZ13 -> 3954.3095 | BD14: =(BA14-BA13)/2+BA13 -> -5556.4018 | BE14: =IF(AND(AZ14-AZ13>0,BA14-BA13>0),ATAN((BA14-BA13)/(AZ14-AZ13)),IF(AND(AZ14-AZ13<0,BA14-BA13>0),PI()+ATAN((BA14-BA13)/(AZ14-AZ13)),IF(AND(AZ14-AZ13<0,BA14-BA13<0),PI()+ATAN((BA14-BA13)/(AZ14-AZ13)),2*PI()+ATAN((BA14-BA13)/(AZ14-AZ13))))) -> 3.7450342 | BF14: =BE14*180/PI() -> 214.57466 | BG14: =BE14+PI()/2 -> 5.3158306 | BH14: =BG14*180/PI() -> 304.57466 | BI14: =COS(BG14)*(BK14-(BB14*F13))+BC14 -> 14010.615 | BJ14: =SIN(BG14)*(BK14-(BB14*F13))+BD14 -> -20147.651 | BK14: =BB14*VLOOKUP(F13,$AW$7:$AX$12,2,FALSE) -> 18079 | BL14: =IF(ABS(AZ14-AZ13)>ABS(BA14-BA13),"X","Y") -> X | BM14: =IF(BL14="Y",BI14,BJ14) -> -20147.651 | BN14: =IF(BL14="Y",BJ14,BI14) -> 14010.615
C15: =IF(G7=5,"E-A",IF(G7>5,"E-F","")) -> E-F | D15: =Print!D18 -> 2600 | E15: =Print!E18 -> 0 | F15: =Print!G18 -> 0.05 | G15: =Print!I18 -> 0 | H15: =IF(G7>=5,"E","") -> E | I15: =Print!L18 -> 0 | K15: =Print!M18 -> 0 | L15: =Print!N18 -> 0 | M15: =Print!O18 -> #N/A | O15: =IF(LEFT(Print!P18,3)="180",180,0) -> 0 | Q15: =IF(OR(LEFT(C15,1)="A",RIGHT(C15,1)="A"),"A","") | R15: =IF(OR(LEFT(C15,1)="B",RIGHT(C15,1)="B"),"B","") | S15: =IF(OR(LEFT(C15,1)="C",RIGHT(C15,1)="C"),"C","") | T15: =IF(OR(LEFT(C15,1)="D",RIGHT(C15,1)="D"),"D","") | U15: =IF(OR(LEFT(C15,1)="E",RIGHT(C15,1)="E"),"E","") -> E | V15: =IF(OR(LEFT(C15,1)="F",RIGHT(C15,1)="F"),"F","") -> F | W15: =IF(OR(LEFT(C15,1)="G",RIGHT(C15,1)="G"),"G","") | X15: =IF(OR(LEFT(C15,1)="H",RIGHT(C15,1)="H"),"H","") | Z15: =SQRT((D15*D15)-(AB15*AB15)) -> 2600 | AB15: =VLOOKUP(LEFT(C15,1),HEIGHT,2,FALSE)-VLOOKUP(RIGHT(C15,1),HEIGHT,2,FALSE) -> 0 | AD15: E | AE15: =IF(O15=180,PI(),IF(Main!O17="R",PI()-IF(G7=5,ACOS(((Z15*Z15)+(Z14*Z14)-(Y26*Y26))/(2*Z14*Z15)),IF(G7<5,0,ACOS(((Z15*Z15)+(Z14*Z14)-(VLOOKUP("D-F",C25:Y44,23,FALSE)*VLOOKUP("D-F",C25:Y44,23,FALSE)))/(2*Z14*Z15))))+PI(),IF(G7=5,ACOS(((Z15*Z15)+(Z14*Z14)-(Y26*Y26))/(2*Z14*Z15)),IF(G7<5,0,ACOS(((Z15*Z15)+(Z14*Z14)-(VLOOKUP("D-F",C25:Y44,23,FALSE)*VLOOKUP("D-F",C25:Y44,23,FALSE)))/(2*Z14*Z15)))))) -> 2.7746712 | AF15: =AE15*180/PI() -> 158.97695 | AG15: =IF(G7<6,0,AG14-(Z15*COS(PI()-AE15+PI()-AE14+(PI()-AE12-AE13)))) -> -1780.3326 | AH15: =IF(G7<6,0,AH14+(Z15*SIN(PI()-AE15+PI()-AE14+(PI()-AE12-AE13)))) -> -2285.7901 | AI15: =IF(ISERROR(AK15*COS(AL15)),0,AK15*COS(AL15)) -> 0 | AJ15: =IF(ISERROR(AK15*SIN(AL15)),0,AK15*SIN(AL15)) -> 0 | AK15: =M15 -> #N/A | AL15: =PI()+AE12-(PI()-AE13)-(PI()-AE14)-(PI()-AE15)-AE15/2 -> 0.45682031 | AM15: =AG12+AI13 -> 6902.0366 | AN15: =AH12+AJ13 -> -3524.8249 | AO15: =AG12 -> 6902.0366 | AP15: =AH12 -> -3524.8249 | AQ15: =AL15*180/PI() -> 26.173876 | AT15: =AM21 -> -1078.4163 | AU15: =AN21 -> -4789.2504 | AY15: D | AZ15: =AM21 -> -1078.4163 | BA15: =AN21 -> -4789.2504 | BB15: =SQRT(((AZ15-AZ14)*(AZ15-AZ14))+((BA15-BA14)*(BA15-BA14))) -> 3490 | BC15: =(AZ15-AZ14)/2+AZ14 -> -35.916943 | BD15: =(BA15-BA14)/2+BA14 -> -6188.6146 | BE15: =IF(AND(AZ15-AZ14>0,BA15-BA14>0),ATAN((BA15-BA14)/(AZ15-AZ14)),IF(AND(AZ15-AZ14<0,BA15-BA14>0),PI()+ATAN((BA15-BA14)/(AZ15-AZ14)),IF(AND(AZ15-AZ14<0,BA15-BA14<0),PI()+ATAN((BA15-BA14)/(AZ15-AZ14)),2*PI()+ATAN((BA15-BA14)/(AZ15-AZ14))))) -> 2.2110773 | BF15: =BE15*180/PI() -> 126.6854 | BG15: =IF(BE15<0,BE15-PI()/2,BE15+PI()/2) -> 3.7818737 | BH15: =BG15*180/PI() -> 216.6854 | BI15: =COS(BG15)*(BK15-(BB15*F14))+BC15 -> -6962.7697 | BJ15: =SIN(BG15)*(BK15-(BB15*F14))+BD15 -> -11348.986 | BK15: =BB15*VLOOKUP(F14,$AW$7:$AX$12,2,FALSE) -> 8812.25 | BL15: =IF(ABS(AZ15-AZ14)>ABS(BA15-BA14),"X","Y") -> Y | BM15: =IF(BL15="Y",BI15,BJ15) -> -6962.7697 | BN15: =IF(BL15="Y",BJ15,BI15) -> -11348.986
C16: =IF(G7=6,"F-A",IF(G7>6,"F-G","")) -> F-A | D16: =Print!D19 -> 7480 | E16: =Print!E19 -> 0 | F16: =Print!G19 -> 0.05 | G16: =Print!I19 -> - | H16: =IF(G7>=6,"F","") -> F | I16: =Print!L19 -> 0 | K16: =Print!M19 -> - | L16: =Print!N19 -> - | M16: =Print!O19 -> #N/A | O16: =IF(LEFT(Print!P19,3)="180",180,0) -> 0 | Q16: =IF(OR(LEFT(C16,1)="A",RIGHT(C16,1)="A"),"A","") -> A | R16: =IF(OR(LEFT(C16,1)="B",RIGHT(C16,1)="B"),"B","") | S16: =IF(OR(LEFT(C16,1)="C",RIGHT(C16,1)="C"),"C","") | T16: =IF(OR(LEFT(C16,1)="D",RIGHT(C16,1)="D"),"D","") | U16: =IF(OR(LEFT(C16,1)="E",RIGHT(C16,1)="E"),"E","") | V16: =IF(OR(LEFT(C16,1)="F",RIGHT(C16,1)="F"),"F","") -> F | W16: =IF(OR(LEFT(C16,1)="G",RIGHT(C16,1)="G"),"G","") | X16: =IF(OR(LEFT(C16,1)="H",RIGHT(C16,1)="H"),"H","") | Z16: =SQRT((D16*D16)-(AB16*AB16)) -> 7480 | AB16: =VLOOKUP(LEFT(C16,1),HEIGHT,2,FALSE)-VLOOKUP(RIGHT(C16,1),HEIGHT,2,FALSE) -> 0 | AD16: F | AE16: =IF(O16=180,PI(),IF(Main!O18="R",PI()-IF(G7=6,ACOS(((Z16*Z16)+(Z15*Z15)-(Y27*Y27))/(2*Z15*Z16)),IF(G7<6,0,ACOS(((Z16*Z16)+(Z15*Z15)-(VLOOKUP("E-G",C25:Y44,23,FALSE)*VLOOKUP("E-G",C25:Y44,23,FALSE)))/(2*Z15*Z16))))+PI(),IF(G7=6,ACOS(((Z16*Z16)+(Z15*Z15)-(Y27*Y27))/(2*Z15*Z16)),IF(G7<6,0,ACOS(((Z16*Z16)+(Z15*Z15)-(VLOOKUP("E-G",C25:Y44,23,FALSE)*VLOOKUP("E-G",C25:Y44,23,FALSE)))/(2*Z15*Z16)))))) -> 1.7217183 | AF16: =AE16*180/PI() -> 98.64719 | AG16: =IF(G7<7,0,AG15-Z16*COS(PI()-AE16+PI()-AE15+PI()-AE14+(PI()-AE12-AE13))) -> 0 | AH16: =IF(G7<7,0,AH15+Z16*SIN(PI()-AE16+PI()-AE15+PI()-AE14+(PI()-AE12-AE13))) -> 0 | AI16: =IF(ISERROR(AK16*COS(AL16)),0,AK16*COS(AL16)) -> 0 | AJ16: =IF(ISERROR(AK16*SIN(AL16)),0,AK16*SIN(AL16)) -> 0 | AK16: =M16 -> #N/A | AL16: =PI()+AE12-(PI()-AE13)-(PI()-AE14)-(PI()-AE15)-(PI()-AE16)-AE16/2 -> -0.43657759 | AM16: =AG12 -> 6902.0366 | AN16: =AH12 -> -3524.8249 | AO16: =AG13 -> 1006.5824 | AP16: =AH13 -> -7587.9788 | AQ16: =AL16*180/PI() -> -25.014054 | AS16: =AS11/AR10 -> 0.1043533 | AT16: =AM24 -> -1780.3326 | AU16: =AN24 -> -2285.7901 | AY16: E | AZ16: =AM24 -> -1780.3326 | BA16: =AN24 -> -2285.7901 | BB16: =SQRT(((AZ16-AZ15)*(AZ16-AZ15))+((BA16-BA15)*(BA16-BA15))) -> 2600 | BC16: =(AZ16-AZ15)/2+AZ15 -> -1429.3744 | BD16: =(BA16-BA15)/2+BA15 -> -3537.5202 | BE16: =IF(AND(AZ16-AZ15>0,BA16-BA15>0),ATAN((BA16-BA15)/(AZ16-AZ15)),IF(AND(AZ16-AZ15<0,BA16-BA15>0),PI()+ATAN((BA16-BA15)/(AZ16-AZ15)),IF(AND(AZ16-AZ15<0,BA16-BA15<0),PI()+ATAN((BA16-BA15)/(AZ16-AZ15)),2*PI()+ATAN((BA16-BA15)/(AZ16-AZ15))))) -> 1.8441559 | BF16: =BE16*180/PI() -> 105.66235 | BG16: =IF(BE16<0,BE16-PI()/2,BE16+PI()/2) -> 3.4149523 | BH16: =BG16*180/PI() -> 195.66235 | BI16: =COS(BG16)*(BK16-(BB16*F15))+BC16 -> -7625.4387 | BJ16: =SIN(BG16)*(BK16-(BB16*F15))+BD16 -> -5274.7631 | BK16: =BB16*VLOOKUP(F15,$AW$7:$AX$12,2,FALSE) -> 6565 | BL16: =IF(ABS(AZ16-AZ15)>ABS(BA16-BA15),"X","Y") -> Y | BM16: =IF(BL16="Y",BI16,BJ16) -> -7625.4387 | BN16: =IF(BL16="Y",BJ16,BI16) -> -5274.7631
C17: =IF(G7=7,"G-A",IF(G7>7,"G-H","")) | D17: =Print!D20 -> - | E17: =Print!E20 -> 0 | F17: =Print!G20 -> 0.05 | G17: =Print!I20 -> - | H17: =IF(G7>=7,"G","") | I17: =Print!L20 -> 0 | K17: =Print!M20 -> - | L17: =Print!N20 -> - | M17: =Print!O20 -> #N/A | O17: =IF(LEFT(Print!P20,3)="180",180,0) -> 0 | Q17: =IF(OR(LEFT(C17,1)="A",RIGHT(C17,1)="A"),"A","") | R17: =IF(OR(LEFT(C17,1)="B",RIGHT(C17,1)="B"),"B","") | S17: =IF(OR(LEFT(C17,1)="C",RIGHT(C17,1)="C"),"C","") | T17: =IF(OR(LEFT(C17,1)="D",RIGHT(C17,1)="D"),"D","") | U17: =IF(OR(LEFT(C17,1)="E",RIGHT(C17,1)="E"),"E","") | V17: =IF(OR(LEFT(C17,1)="F",RIGHT(C17,1)="F"),"F","") | W17: =IF(OR(LEFT(C17,1)="G",RIGHT(C17,1)="G"),"G","") | X17: =IF(OR(LEFT(C17,1)="H",RIGHT(C17,1)="H"),"H","") | Z17: =SQRT((D17*D17)-(AB17*AB17)) -> #VALUE! | AB17: =VLOOKUP(LEFT(C17,1),HEIGHT,2,FALSE)-VLOOKUP(RIGHT(C17,1),HEIGHT,2,FALSE) -> 0 | AD17: G | AE17: =IF(O17=180,PI(),IF(Main!O19="R",PI()-IF(G7=7,ACOS(((Z17*Z17)+(Z16*Z16)-(Y28*Y28))/(2*Z16*Z17)),IF(G7<7,0,ACOS(((Z17*Z17)+(Z16*Z16)-(VLOOKUP("F-H",C25:Y44,23,FALSE)*VLOOKUP("F-H",C25:Y44,23,FALSE)))/(2*Z16*Z17))))+PI(),IF(G7=7,ACOS(((Z17*Z17)+(Z16*Z16)-(Y28*Y28))/(2*Z16*Z17)),IF(G7<7,0,ACOS(((Z17*Z17)+(Z16*Z16)-(VLOOKUP("F-H",C25:Y44,23,FALSE)*VLOOKUP("F-H",C25:Y44,23,FALSE)))/(2*Z16*Z17)))))) -> 0 | AF17: =AE17*180/PI() -> 0 | AG17: =IF(G7<8,0,Z18*COS(AE11)) -> 0 | AH17: =IF(G7<8,0,-Z18*SIN(AE11)) -> 0 | AI17: =IF(ISERROR(AK17*COS(AL17)),0,AK17*COS(AL17)) -> 0 | AJ17: =IF(ISERROR(AK17*SIN(AL17)),0,AK17*SIN(AL17)) -> 0 | AK17: =M17 -> #N/A | AL17: =PI()+AE12-(PI()-AE13)-(PI()-AE14)-(PI()-AE15)-(PI()-AE16)-(PI()-AE17)-AE17/2 -> -2.7173111 | AM17: =AM15 -> 6902.0366 | AN17: =AN15 -> -3524.8249 | AO17: =AO11 -> 0 | AP17: =AP11 -> 0 | AQ17: =AL17*180/PI() -> -155.69046 | AS17: =0.0085-(0.001*G7) -> 0.0025 | AT17: =AM27 -> 0 | AU17: =AN27 -> 0 | AY17: F | AZ17: =AM27 -> 0 | BA17: =AN27 -> 0 | BB17: =SQRT(((AZ17-AZ16)*(AZ17-AZ16))+((BA17-BA16)*(BA17-BA16))) -> 2897.3126 | BC17: =(AZ17-AZ16)/2+AZ16 -> -890.16629 | BD17: =(BA17-BA16)/2+BA16 -> -1142.895 | BE17: =IF(AND(AZ17-AZ16>0,BA17-BA16>0),ATAN((BA17-BA16)/(AZ17-AZ16)),IF(AND(AZ17-AZ16<0,BA17-BA16>0),PI()+ATAN((BA17-BA16)/(AZ17-AZ16)),IF(AND(AZ17-AZ16<0,BA17-BA16<0),PI()+ATAN((BA17-BA16)/(AZ17-AZ16)),2*PI()+ATAN((BA17-BA16)/(AZ17-AZ16))))) -> 0.90907318 | BF17: =BE17*180/PI() -> 52.086057 | BG17: =IF(BE17<0,BE17-PI()/2,BE17+PI()/2) -> 2.4798695 | BH17: =BG17*180/PI() -> 142.08606 | BI17: =COS(BG17)*(BK17-(BB17*F16))+BC17 -> -6547.4967 | BJ17: =SIN(BG17)*(BK17-(BB17*F16))+BD17 -> 3263.4281 | BK17: =BB17*VLOOKUP(F16,$AW$7:$AX$12,2,FALSE) -> 7315.7144 | BL17: =IF(ABS(AZ17-AZ16)>ABS(BA17-BA16),"X","Y") -> Y | BM17: =IF(BL17="Y",BI17,BJ17) -> -6547.4967 | BN17: =IF(BL17="Y",BJ17,BI17) -> 3263.4281
C18: =IF(G7=8,"H-A",IF(G7>8,"NO MORE!","")) | D18: =Print!D21 -> - | E18: =Print!E21 -> 0 | F18: =Print!G21 -> 0.05 | G18: =Print!I21 -> - | H18: =IF(G7>=8,"H","") | I18: =Print!L21 -> 0 | K18: =Print!M21 -> - | L18: =Print!N21 -> - | M18: =Print!O21 -> #N/A | O18: =IF(LEFT(Print!P21,3)="180",180,0) -> 0 | Q18: =IF(OR(LEFT(C18,1)="A",RIGHT(C18,1)="A"),"A","") | R18: =IF(OR(LEFT(C18,1)="B",RIGHT(C18,1)="B"),"B","") | S18: =IF(OR(LEFT(C18,1)="C",RIGHT(C18,1)="C"),"C","") | T18: =IF(OR(LEFT(C18,1)="D",RIGHT(C18,1)="D"),"D","") | U18: =IF(OR(LEFT(C18,1)="E",RIGHT(C18,1)="E"),"E","") | V18: =IF(OR(LEFT(C18,1)="F",RIGHT(C18,1)="F"),"F","") | W18: =IF(OR(LEFT(C18,1)="G",RIGHT(C18,1)="G"),"G","") | X18: =IF(OR(LEFT(C18,1)="H",RIGHT(C18,1)="H"),"H","") | Z18: =SQRT((D18*D18)-(AB18*AB18)) -> #VALUE! | AB18: =VLOOKUP(LEFT(C18,1),HEIGHT,2,FALSE)-VLOOKUP(RIGHT(C18,1),HEIGHT,2,FALSE) -> 0 | AD18: H | AE18: =IF(O18=180,PI(),IF(Main!O20="R",PI()-IF(G7=8,ACOS(((Z18*Z18)+(Z17*Z17)-(Y29*Y29))/(2*Z17*Z18)),IF(G7<8,0,0))+PI(),IF(G7=8,ACOS(((Z18*Z18)+(Z17*Z17)-(Y29*Y29))/(2*Z17*Z18)),IF(G7<8,0,0)))) -> 0 | AF18: =AE18*180/PI() -> 0 | AG18: =0 -> 0 | AH18: =0 -> 0 | AI18: =IF(ISERROR(AK18*COS(AL18)),0,AK18*COS(AL18)) -> 0 | AJ18: =IF(ISERROR(AK18*SIN(AL18)),0,AK18*SIN(AL18)) -> 0 | AK18: =M18 -> #N/A | AL18: =PI()+AE12-(PI()-AE13)-(PI()-AE14)-(PI()-AE15)-(PI()-AE16)-(PI()-AE17)-(PI()-AE18)-AE18/2 -> -5.8589038 | AM18: =IF(G7>3,AG13+AI14,AG13+AI11) -> 1006.5824 | AN18: =IF(G7>3,AH13+AJ14,AH13+AJ11) -> -7587.9788 | AQ18: =AL18*180/PI() -> -335.69046 | AT18: =AM30 -> 0 | AU18: =AN30 -> 0 | AY18: G | AZ18: =AM30 -> 0 | BA18: =AN30 -> 0 | BB18: =SQRT(((AZ18-AZ17)*(AZ18-AZ17))+((BA18-BA17)*(BA18-BA17))) -> 0 | BC18: =(AZ18-AZ17)/2+AZ17 -> 0 | BD18: =(BA18-BA17)/2+BA17 -> 0 | BE18: =IF(AND(AZ18-AZ17>0,BA18-BA17>0),ATAN((BA18-BA17)/(AZ18-AZ17)),IF(AND(AZ18-AZ17<0,BA18-BA17>0),PI()+ATAN((BA18-BA17)/(AZ18-AZ17)),IF(AND(AZ18-AZ17<0,BA18-BA17<0),PI()+ATAN((BA18-BA17)/(AZ18-AZ17)),2*PI()+ATAN((BA18-BA17)/(AZ18-AZ17))))) -> #DIV/0! | BF18: =BE18*180/PI() -> #DIV/0! | BG18: =IF(BE18<0,BE18-PI()/2,BE18+PI()/2) -> #DIV/0! | BH18: =BG18*180/PI() -> #DIV/0! | BI18: =COS(BG18)*(BK18-(BB18*F17))+BC18 -> #DIV/0! | BJ18: =SIN(BG18)*(BK18-(BB18*F17))+BD18 -> #DIV/0! | BK18: =BB18*VLOOKUP(F17,$AW$7:$AX$12,2,FALSE) -> 0 | BL18: =IF(ABS(AZ18-AZ17)>ABS(BA18-BA17),"X","Y") -> Y | BM18: =IF(BL18="Y",BI18,BJ18) -> #DIV/0! | BN18: =IF(BL18="Y",BJ18,BI18) -> #DIV/0!
K19: Corner Fitting | L19: =Print!#REF! -> #REF! | AM19: =AG13 -> 1006.5824 | AN19: =AH13 -> -7587.9788 | AY19: H | AZ19: =AM33 -> 0 | BA19: =AN33 -> 0 | BB19: =SQRT(((AZ19-AZ18)*(AZ19-AZ18))+((BA19-BA18)*(BA19-BA18))) -> 0 | BC19: =(AZ19-AZ18)/2+AZ18 -> 0 | BD19: =(BA19-BA18)/2+BA18 -> 0 | BE19: =IF(AND(AZ19-AZ18>0,BA19-BA18>0),ATAN((BA19-BA18)/(AZ19-AZ18)),IF(AND(AZ19-AZ18<0,BA19-BA18>0),PI()+ATAN((BA19-BA18)/(AZ19-AZ18)),IF(AND(AZ19-AZ18<0,BA19-BA18<0),PI()+ATAN((BA19-BA18)/(AZ19-AZ18)),2*PI()+ATAN((BA19-BA18)/(AZ19-AZ18))))) -> #DIV/0! | BF19: =BE19*180/PI() -> #DIV/0! | BG19: =IF(BE19<0,BE19-PI()/2,BE19+PI()/2) -> #DIV/0! | BH19: =BG19*180/PI() -> #DIV/0! | BI19: =COS(BG19)*(BK19-(BB19*F18))+BC19 -> #DIV/0! | BJ19: =SIN(BG19)*(BK19-(BB19*F18))+BD19 -> #DIV/0! | BK19: =BB19*VLOOKUP(F18,$AW$7:$AX$12,2,FALSE) -> 0 | BL19: =IF(ABS(AZ19-AZ18)>ABS(BA19-BA18),"X","Y") -> Y | BM19: =IF(BL19="Y",BI19,BJ19) -> #DIV/0! | BN19: =IF(BL19="Y",BJ19,BI19) -> #DIV/0!
C20: =IF(ISERROR(IF(AS13="ERROR","ERROR","")),"",IF(AS13="ERROR","- ERROR - REMEASURE","")) -> - ERROR - REMEASURE | G20: Error | I20: Comments: | AM20: =AM18 -> 1006.5824 | AN20: =AN18 -> -7587.9788
G21: =IF(G7=3,0,AS16) -> 0.1043533 | I21: =Print!K24 -> 0 | AE21: =PI()-ACOS(((Z15*Z15)+(Z14*Z14)-(VLOOKUP("D-F",C25:Y44,23,FALSE)*VLOOKUP("D-F",C25:Y44,23,FALSE)))/(2*Z14*Z15))+PI() -> 3.5085141 | AF21: =PI()-ACOS(((Z15*Z15)+(Z14*Z14)-(VLOOKUP("D-F",C25:Y44,23,FALSE)*VLOOKUP("D-F",C25:Y44,23,FALSE)))/(2*Z14*Z15)) -> 0.36692141 | AH21: =(Z13*SIN(PI()-AE12-AE13)) -> -4063.1539 | AM21: =IF(G7>4,AG14+AI15,AG14+AI11) -> -1078.4163 | AN21: =IF(G7>4,AH14+AJ15,AH10+AJ11) -> -4789.2504 | BD21: Raw angles | BT21: bt | BW21: bw | BZ21: bz | CC21: cc
I22: =Print!K25 -> 0 | AE22: =VLOOKUP("D-F",C25:Y44,23,FALSE) -> 5990 | AM22: =AG14 -> -1078.4163 | AN22: =AH14 -> -4789.2504 | AZ22: offsets | BB22: Act Dist | BD22: =ATAN((BA12-BA11)/(AZ12-AZ11)) -> 0 | BE22: =BD22*180/PI() -> 0 | BG22: =IF(BL12="X",HLOOKUP("Y",AZ10:BA19,3,FALSE)-HLOOKUP("Y",AZ10:BA19,2,FALSE),HLOOKUP("X",AZ10:BA19,3,FALSE)-HLOOKUP("X",AZ10:BA19,2,FALSE)) -> 0 | BH22: =BG22/10 -> 0 | BJ22: =IF(BL13="X",HLOOKUP("Y",AZ10:BA19,4,FALSE)-HLOOKUP("Y",AZ10:BA19,3,FALSE),HLOOKUP("X",AZ10:BA19,4,FALSE)-HLOOKUP("X",AZ10:BA19,3,FALSE)) -> 2532.0366 | BK22: =BJ22/10 -> 253.20366 | BM22: =IF(BL14="X",HLOOKUP("Y",AZ10:BA19,5,FALSE)-HLOOKUP("Y",AZ10:BA19,4,FALSE),HLOOKUP("X",AZ10:BA19,5,FALSE)-HLOOKUP("X",AZ10:BA19,4,FALSE)) -> -4063.1539 | BN22: =BM22/10 -> -406.31539 | BP22: =IF(BL15="X",HLOOKUP("Y",AZ10:BA19,6,FALSE)-HLOOKUP("Y",AZ10:BA19,5,FALSE),HLOOKUP("X",AZ10:BA19,6,FALSE)-HLOOKUP("X",AZ10:BA19,5,FALSE)) -> -2084.9987 | BQ22: =BP22/10 -> -208.49987 | BS22: =IF(BL16="X",HLOOKUP("Y",AZ10:BA19,7,FALSE)-HLOOKUP("Y",AZ10:BA19,6,FALSE),HLOOKUP("X",AZ10:BA19,7,FALSE)-HLOOKUP("X",AZ10:BA19,6,FALSE)) -> -701.91631 | BT22: =BS22/10 -> -70.191631 | BV22: =IF(BL17="X",HLOOKUP("Y",AZ10:BA19,8,FALSE)-HLOOKUP("Y",AZ10:BA19,7,FALSE),HLOOKUP("X",AZ10:BA19,8,FALSE)-HLOOKUP("X",AZ10:BA19,7,FALSE)) -> 1780.3326 | BW22: =BV22/10 -> 178.03326 | BY22: =IF(BL18="X",HLOOKUP("Y",AZ10:BA19,9,FALSE)-HLOOKUP("Y",AZ10:BA19,8,FALSE),HLOOKUP("X",AZ10:BA19,9,FALSE)-HLOOKUP("X",AZ10:BA19,8,FALSE)) -> 0 | BZ22: =BY22/10 -> 0 | CB22: =IF(BL19="X",HLOOKUP("Y",AZ10:BA19,10,FALSE)-HLOOKUP("Y",AZ10:BA19,9,FALSE),HLOOKUP("X",AZ10:BA19,10,FALSE)-HLOOKUP("X",AZ10:BA19,9,FALSE)) -> 0 | CC22: =CB22/10 -> 0
C23: DIAGONAL POINT TO POINT | I23: =Print!K26 -> 0 | AM23: =AM21 -> -1078.4163 | AN23: =AN21 -> -4789.2504 | AZ23: =IF(ISERROR(BB12*F11),0,BB12*F11) -> 218.5 | BB23: =IF(ISERROR(SQRT((BB12*BB12)+((AB11-BD39)*(AB11-BD39)))),0,SQRT((BB12*BB12)+((AB11-BD39)*(AB11-BD39)))) -> 0 | BD23: =ATAN((BA13-BA12)/(AZ13-AZ12)) -> -0.94786479 | BE23: =BD23*180/PI() -> -54.308652 | BG23: =HLOOKUP(BL12,AZ10:BA19,3,FALSE)-HLOOKUP(BL12,AZ10:BA19,2,FALSE) -> 4370 | BH23: =BG23/10 -> 437 | BJ23: =HLOOKUP(BL13,AZ10:BA19,4,FALSE)-HLOOKUP(BL13,AZ10:BA19,3,FALSE) -> -3524.8249 | BK23: =BJ23/10 -> -352.48249 | BM23: =HLOOKUP(BL14,AZ10:BA19,5,FALSE)-HLOOKUP(BL14,AZ10:BA19,4,FALSE) -> -5895.4542 | BN23: =BM23/10 -> -589.54542 | BP23: =HLOOKUP(BL15,AZ10:BA19,6,FALSE)-HLOOKUP(BL15,AZ10:BA19,5,FALSE) -> 2798.7284 | BQ23: =BP23/10 -> 279.87284 | BS23: =HLOOKUP(BL16,AZ10:BA19,7,FALSE)-HLOOKUP(BL16,AZ10:BA19,6,FALSE) -> 2503.4603 | BT23: =BS23/10 -> 250.34603 | BV23: =HLOOKUP(BL17,AZ10:BA19,8,FALSE)-HLOOKUP(BL17,AZ10:BA19,7,FALSE) -> 2285.7901 | BW23: =BV23/10 -> 228.57901 | BY23: =HLOOKUP(BL18,AZ10:BA19,9,FALSE)-HLOOKUP(BL18,AZ10:BA19,8,FALSE) -> 0 | BZ23: =BY23/10 -> 0 | CB23: =HLOOKUP(BL19,AZ10:BA19,10,FALSE)-HLOOKUP(BL19,AZ10:BA19,9,FALSE) -> 0 | CC23: =CB23/10 -> 0
I24: =Print!K27 -> 0 | AE24: BOX | AG24: x diff | AH24: y diff | AM24: =IF(G7>5,AG15+AI16,AG15+AI11) -> -1780.3326 | AN24: =IF(G7>5,AH15+AJ16,AH15+AJ11) -> -2285.7901 | AZ24: =IF(ISERROR(BB13*F12),0,BB13*F12) -> 217 | BB24: =IF(ISERROR(SQRT((BB13*BB13)+((AB12-BD40)*(AB12-BD40)))),0,SQRT((BB13*BB13)+((AB12-BD40)*(AB12-BD40)))) -> 0 | BD24: =ATAN((BA14-BA13)/(AZ14-AZ13)) -> 0.60344159 | BE24: =BD24*180/PI() -> 34.574656 | BF24: 1 | BG24: =BG25-BH23 -> 0 | BH24: =IF($BK$12=0,IF($BL$12="X",$BA$11,$AZ$11),IF($AS$34,(SQRT(($BK$12*$BK$12)-((BG24-$BN$12)*(BG24-$BN$12)))+$BM$12),(-SQRT(($BK$12*$BK$12)-((BG24-$BN$12)*(BG24-$BN$12)))+$BM$12))) -> 0 | BI24: 1 | BJ24: =HLOOKUP(BL13,AZ10:BA19,3,FALSE) -> 0 | BK24: =IF($BK$13=0,IF($BL$13="X",$BA$12,$AZ$12),IF($AT$34,(SQRT(($BK$13*$BK$13)-((BJ24-$BN$13)*(BJ24-$BN$13)))+$BM$13),(-SQRT(($BK$13*$BK$13)-((BJ24-$BN$13)*(BJ24-$BN$13)))+$BM$13))) -> 4370 | BL24: 1 | BM24: =HLOOKUP(BL14,AZ10:BA19,4,FALSE) -> 6902.0366 | BN24: =IF($BK$14=0,IF($BL$14="X",$BA$13,$AZ$13),IF($AU$34,(SQRT(($BK$14*$BK$14)-((BM24-$BN$14)*(BM24-$BN$14)))+$BM$14),(-SQRT(($BK$14*$BK$14)-((BM24-$BN$14)*(BM24-$BN$14)))+$BM$14))) -> -3524.8249 | BO24: 1 | BP24: =HLOOKUP(BL15,AZ10:BA19,5,FALSE) -> -7587.9788 | BQ24: =IF($BK$15=0,IF(BL15="X",$BA$14,$AZ$14),IF($AV$34,(SQRT(($BK$15*$BK$15)-((BP24-$BN$15)*(BP24-$BN$15)))+$BM$15),(-SQRT(($BK$15*$BK$15)-((BP24-$BN$15)*(BP24-$BN$15)))+$BM$15))) -> 1006.5824 | BR24: 1 | BS24: =HLOOKUP(BL16,AZ10:BA19,6,FALSE) -> -4789.2504 | BT24: =IF($BK$16=0,IF(BL16="X",$BA$15,$AZ$15),IF($AW$34,(SQRT(($BK$16*$BK$16)-((BS24-$BN$16)*(BS24-$BN$16)))+$BM$16),(-SQRT(($BK$16*$BK$16)-((BS24-$BN$16)*(BS24-$BN$16)))+$BM$16))) -> -1078.4163 | BU24: 1 | BV24: =HLOOKUP(BL17,AZ10:BA19,7,FALSE) -> -2285.7901 | BW24: =IF($BK$17=0,IF(BL17="X",$BA$16,$AZ$16),IF($AX$34,(SQRT(($BK$17*$BK$17)-((BV24-$BN$17)*(BV24-$BN$17)))+$BM$17),(-SQRT(($BK$17*$BK$17)-((BV24-$BN$17)*(BV24-$BN$17)))+$BM$17))) -> -1780.3326 | BX24: 1 | BY24: =HLOOKUP(BL18,AZ10:BA19,8,FALSE) -> 0 | BZ24: =IF($BK$18=0,IF(BL18="X",$BA$17,$AZ$17),IF($AY$34,(SQRT(($BK$18*$BK$18)-((BY24-$BN$18)*(BY24-$BN$18)))+$BM$18),(-SQRT(($BK$18*$BK$18)-((BY24-$BN$18)*(BY24-$BN$18)))+$BM$18))) -> 0 | CA24: 1 | CB24: =HLOOKUP(BL19,AZ10:BA19,9,FALSE) -> 0 | CC24: =IF($BK$19=0,IF(BL19="X",$BA$18,$AZ$18),IF($AZ$34,(SQRT(($BK$19*$BK$19)-((CB24-$BN$19)*(CB24-$BN$19)))+$BM$19),(-SQRT(($BK$19*$BK$19)-((CB24-$BN$19)*(CB24-$BN$19)))+$BM$19))) -> 0
B25: 1 | C25: =IF(G7<4,"","A-C") -> A-C | D25: =Print!D28 -> 7750 | I25: =Print!K28 -> 0 | Y25: =SQRT((D25*D25)-(AA25*AA25)) -> 7750 | AA25: =VLOOKUP(LEFT(C25,1),HEIGHT,2,FALSE)-VLOOKUP(RIGHT(C25,1),HEIGHT,2,FALSE) -> 0 | AG25: =MAX(AG11:AG18)-MIN(AG11:AG18) -> 8682.3692 | AH25: =MAX(AH11:AH18)-MIN(AH11:AH18) -> 7587.9788 | AI25: =IF(AG25>AH25,"X","Y") -> X | AM25: =AG15 -> -1780.3326 | AN25: =AH15 -> -2285.7901 | AZ25: =IF(ISERROR(BB14*F13),0,BB14*F13) -> 358 | BB25: =IF(ISERROR(SQRT((BB14*BB14)+((AB13-BD41)*(AB13-BD41)))),0,SQRT((BB14*BB14)+((AB13-BD41)*(AB13-BD41)))) -> 0 | BD25: =ATAN((BA15-BA14)/(AZ15-AZ14)) -> -0.93051531 | BE25: =BD25*180/PI() -> -53.3146 | BF25: 2 | BG25: =HLOOKUP(BL12,AZ10:BA19,2,FALSE)+BH23 -> 437 | BH25: =IF($BK$12=0,BH24+$BH$22,IF($AS$33,(SQRT(($BK$12*$BK$12)-((BG25-$BN$12)*(BG25-$BN$12)))+$BM$12),(-SQRT(($BK$12*$BK$12)-((BG25-$BN$12)*(BG25-$BN$12)))+$BM$12))) -> -79.164826 | BI25: 2 | BJ25: =BJ24+$BK$23 -> -352.48249 | BK25: =IF($BK$13=0,BK24+$BK$22,IF($AT$33,(SQRT(($BK$13*$BK$13)-((BJ25-$BN$13)*(BJ25-$BN$13)))+$BM$13),(-SQRT(($BK$13*$BK$13)-((BJ25-$BN$13)*(BJ25-$BN$13)))+$BM$13))) -> 4536.5376 | BL25: 2 | BM25: =BM24+$BN$23 -> 6312.4912 | BN25: =IF($BK$14=0,BN24+$BN$22,IF($AU$33,(SQRT(($BK$14*$BK$14)-((BM25-$BN$14)*(BM25-$BN$14)))+$BM$14),(-SQRT(($BK$14*$BK$14)-((BM25-$BN$14)*(BM25-$BN$14)))+$BM$14))) -> -3789.4994 | BO25: 2 | BP25: =BP24+$BQ$23 -> -7308.1059 | BQ25: =IF($BK$15=0,BQ24+$BQ$22,IF($AV$33,(SQRT(($BK$15*$BK$15)-((BP25-$BN$15)*(BP25-$BN$15)))+$BM$15),(-SQRT(($BK$15*$BK$15)-((BP25-$BN$15)*(BP25-$BN$15)))+$BM$15))) -> 868.38833 | BR25: 2 | BS25: =BS24+$BT$23 -> -4538.9044 | BT25: =IF($BK$16=0,BT24+$BT$22,IF($AW$33,(SQRT(($BK$16*$BK$16)-((BS25-$BN$16)*(BS25-$BN$16)))+$BM$16),(-SQRT(($BK$16*$BK$16)-((BS25-$BN$16)*(BS25-$BN$16)))+$BM$16))) -> -1101.8096 | BU25: 2 | BV25: =BV24+$BW$23 -> -2057.2111 | BW25: =IF($BK$17=0,BW24+$BW$22,IF($AX$33,(SQRT(($BK$17*$BK$17)-((BV25-$BN$17)*(BV25-$BN$17)))+$BM$17),(-SQRT(($BK$17*$BK$17)-((BV25-$BN$17)*(BV25-$BN$17)))+$BM$17))) -> -1526.4933 | BX25: 2 | BY25: =BY24+$BZ$23 -> 0 | BZ25: =IF($BK$18=0,BZ24+$BZ$22,IF($AY$33,(SQRT(($BK$18*$BK$18)-((BY25-$BN$18)*(BY25-$BN$18)))+$BM$18),(-SQRT(($BK$18*$BK$18)-((BY25-$BN$18)*(BY25-$BN$18)))+$BM$18))) -> 0 | CA25: 2 | CB25: =CB24+$CC$23 -> 0 | CC25: =IF($BK$19=0,CC24+$CC$22,IF($AZ$33,(SQRT(($BK$19*$BK$19)-((CB25-$BN$19)*(CB25-$BN$19)))+$BM$19),(-SQRT(($BK$19*$BK$19)-((CB25-$BN$19)*(CB25-$BN$19)))+$BM$19))) -> 0
B26: 2 | C26: =IF(G7=4,"B-D",IF(G7>4,"A-D","")) -> A-D | D26: =Print!D29 -> 10420 | I26: =Print!K29 -> 0 | Y26: =SQRT((D26*D26)-(AA26*AA26)) -> 10420 | AA26: =VLOOKUP(LEFT(C26,1),HEIGHT,2,FALSE)-VLOOKUP(RIGHT(C26,1),HEIGHT,2,FALSE) -> 0 | AG26: x-min | AH26: y-min | AM26: =AM24 -> -1780.3326 | AN26: =AN24 -> -2285.7901 | AZ26: =IF(ISERROR(BB15*F14),0,BB15*F14) -> 174.5 | BB26: =IF(ISERROR(SQRT((BB15*BB15)+((AB14-BD42)*(AB14-BD42)))),0,SQRT((BB15*BB15)+((AB14-BD42)*(AB14-BD42)))) -> 0 | BD26: =ATAN((BA16-BA15)/(AZ16-AZ15)) -> -1.2974367 | BE26: =BD26*180/PI() -> -74.337648 | BF26: 3 | BG26: =BG25+$BH$23 -> 874 | BH26: =IF($BK$12=0,BH25+$BH$22,IF($AS$33,(SQRT(($BK$12*$BK$12)-((BG26-$BN$12)*(BG26-$BN$12)))+$BM$12),(-SQRT(($BK$12*$BK$12)-((BG26-$BN$12)*(BG26-$BN$12)))+$BM$12))) -> -140.34201 | BI26: 3 | BJ26: =BJ25+$BK$23 -> -704.96498 | BK26: =IF($BK$13=0,BK25+$BK$22,IF($AT$33,(SQRT(($BK$13*$BK$13)-((BJ26-$BN$13)*(BJ26-$BN$13)))+$BM$13),(-SQRT(($BK$13*$BK$13)-((BJ26-$BN$13)*(BJ26-$BN$13)))+$BM$13))) -> 4718.8259 | BL26: 3 | BM26: =BM25+$BN$23 -> 5722.9458 | BN26: =IF($BK$14=0,BN25+$BN$22,IF($AU$33,(SQRT(($BK$14*$BK$14)-((BM26-$BN$14)*(BM26-$BN$14)))+$BM$14),(-SQRT(($BK$14*$BK$14)-((BM26-$BN$14)*(BM26-$BN$14)))+$BM$14))) -> -4080.1443 | BO26: 3 | BP26: =BP25+$BQ$23 -> -7028.2331 | BQ26: =IF($BK$15=0,BQ25+$BQ$22,IF($AV$33,(SQRT(($BK$15*$BK$15)-((BP26-$BN$15)*(BP26-$BN$15)))+$BM$15),(-SQRT(($BK$15*$BK$15)-((BP26-$BN$15)*(BP26-$BN$15)))+$BM$15))) -> 717.51949 | BR26: 3 | BS26: =BS25+$BT$23 -> -4288.5583 | BT26: =IF($BK$16=0,BT25+$BT$22,IF($AW$33,(SQRT(($BK$16*$BK$16)-((BS26-$BN$16)*(BS26-$BN$16)))+$BM$16),(-SQRT(($BK$16*$BK$16)-((BS26-$BN$16)*(BS26-$BN$16)))+$BM$16))) -> -1134.936 | BU26: 3 | BV26: =BV25+$BW$23 -> -1828.6321 | BW26: =IF($BK$17=0,BW25+$BW$22,IF($AX$33,(SQRT(($BK$17*$BK$17)-((BV26-$BN$17)*(BV26-$BN$17)))+$BM$17),(-SQRT(($BK$17*$BK$17)-((BV26-$BN$17)*(BV26-$BN$17)))+$BM$17))) -> -1294.8212 | BX26: 3 | BY26: =BY25+$BZ$23 -> 0 | BZ26: =IF($BK$18=0,BZ25+$BZ$22,IF($AY$33,(SQRT(($BK$18*$BK$18)-((BY26-$BN$18)*(BY26-$BN$18)))+$BM$18),(-SQRT(($BK$18*$BK$18)-((BY26-$BN$18)*(BY26-$BN$18)))+$BM$18))) -> 0 | CA26: 3 | CB26: =CB25+$CC$23 -> 0 | CC26: =IF($BK$19=0,CC25+$CC$22,IF($AZ$33,(SQRT(($BK$19*$BK$19)-((CB26-$BN$19)*(CB26-$BN$19)))+$BM$19),(-SQRT(($BK$19*$BK$19)-((CB26-$BN$19)*(CB26-$BN$19)))+$BM$19))) -> 0
B27: 3 | C27: =IF(G7=5,"B-D",IF(G7>5,"A-E","")) -> A-E | D27: =Print!D30 -> 8280 | Y27: =SQRT((D27*D27)-(AA27*AA27)) -> 8280 | AA27: =VLOOKUP(LEFT(C27,1),HEIGHT,2,FALSE)-VLOOKUP(RIGHT(C27,1),HEIGHT,2,FALSE) -> 0 | AG27: =MIN(AG11:AG18) -> -1780.3326 | AH27: =MIN(AH11:AH18) -> -7587.9788 | AM27: =IF(G7>6,AG16+AI17,AG16+AI11) -> 0 | AN27: =IF(G7>6,AH16+AJ17,AH16+AJ11) -> 0 | AZ27: =IF(ISERROR(BB16*F15),0,BB16*F15) -> 130 | BB27: =IF(ISERROR(SQRT((BB16*BB16)+((AB15-BD43)*(AB15-BD43)))),0,SQRT((BB16*BB16)+((AB15-BD43)*(AB15-BD43)))) -> 0 | BD27: =ATAN((BA17-BA16)/(AZ17-AZ16)) -> 0.90907318 | BE27: =BD27*180/PI() -> 52.086057 | BF27: 4 | BG27: =BG26+$BH$23 -> 1311 | BH27: =IF($BK$12=0,BH26+$BH$22,IF($AS$33,(SQRT(($BK$12*$BK$12)-((BG27-$BN$12)*(BG27-$BN$12)))+$BM$12),(-SQRT(($BK$12*$BK$12)-((BG27-$BN$12)*(BG27-$BN$12)))+$BM$12))) -> -183.83168 | BI27: 4 | BJ27: =BJ26+$BK$23 -> -1057.4475 | BK27: =IF($BK$13=0,BK26+$BK$22,IF($AT$33,(SQRT(($BK$13*$BK$13)-((BJ27-$BN$13)*(BJ27-$BN$13)))+$BM$13),(-SQRT(($BK$13*$BK$13)-((BJ27-$BN$13)*(BJ27-$BN$13)))+$BM$13))) -> 4917.777 | BL27: 4 | BM27: =BM26+$BN$23 -> 5133.4003 | BN27: =IF($BK$14=0,BN26+$BN$22,IF($AU$33,(SQRT(($BK$14*$BK$14)-((BM27-$BN$14)*(BM27-$BN$14)))+$BM$14),(-SQRT(($BK$14*$BK$14)-((BM27-$BN$14)*(BM27-$BN$14)))+$BM$14))) -> -4398.1973 | BO27: 4 | BP27: =BP26+$BQ$23 -> -6748.3603 | BQ27: =IF($BK$15=0,BQ26+$BQ$22,IF($AV$33,(SQRT(($BK$15*$BK$15)-((BP27-$BN$15)*(BP27-$BN$15)))+$BM$15),(-SQRT(($BK$15*$BK$15)-((BP27-$BN$15)*(BP27-$BN$15)))+$BM$15))) -> 553.21263 | BR27: 4 | BS27: =BS26+$BT$23 -> -4038.2123 | BT27: =IF($BK$16=0,BT26+$BT$22,IF($AW$33,(SQRT(($BK$16*$BK$16)-((BS27-$BN$16)*(BS27-$BN$16)))+$BM$16),(-SQRT(($BK$16*$BK$16)-((BS27-$BN$16)*(BS27-$BN$16)))+$BM$16))) -> -1177.9456 | BU27: 4 | BV27: =BV26+$BW$23 -> -1600.0531 | BW27: =IF($BK$17=0,BW26+$BW$22,IF($AX$33,(SQRT(($BK$17*$BK$17)-((BV27-$BN$17)*(BV27-$BN$17)))+$BM$17),(-SQRT(($BK$17*$BK$17)-((BV27-$BN$17)*(BV27-$BN$17)))+$BM$17))) -> -1082.4965 | BX27: 4 | BY27: =BY26+$BZ$23 -> 0 | BZ27: =IF($BK$18=0,BZ26+$BZ$22,IF($AY$33,(SQRT(($BK$18*$BK$18)-((BY27-$BN$18)*(BY27-$BN$18)))+$BM$18),(-SQRT(($BK$18*$BK$18)-((BY27-$BN$18)*(BY27-$BN$18)))+$BM$18))) -> 0 | CA27: 4 | CB27: =CB26+$CC$23 -> 0 | CC27: =IF($BK$19=0,CC26+$CC$22,IF($AZ$33,(SQRT(($BK$19*$BK$19)-((CB27-$BN$19)*(CB27-$BN$19)))+$BM$19),(-SQRT(($BK$19*$BK$19)-((CB27-$BN$19)*(CB27-$BN$19)))+$BM$19))) -> 0
B28: 4 | C28: =IF(G7=5,"B-E",IF(G7=6,"B-D",IF(G7>6,"A-F",""))) -> B-D | D28: =Print!D31 -> 8300 | Y28: =SQRT((D28*D28)-(AA28*AA28)) -> 8300 | AA28: =VLOOKUP(LEFT(C28,1),HEIGHT,2,FALSE)-VLOOKUP(RIGHT(C28,1),HEIGHT,2,FALSE) -> 0 | AG28: x-max | AH28: y-max | AM28: =AG16 -> 0 | AN28: =AH16 -> 0 | AZ28: =IF(ISERROR(BB17*F16),0,BB17*F16) -> 144.86563 | BB28: =IF(ISERROR(SQRT((BB17*BB17)+((AB16-BD44)*(AB16-BD44)))),0,SQRT((BB17*BB17)+((AB16-BD44)*(AB16-BD44)))) -> 0 | BD28: =ATAN((BA18-BA17)/(AZ18-AZ17)) -> #DIV/0! | BE28: =BD28*180/PI() -> #DIV/0! | BF28: 5 | BG28: =BG27+$BH$23 -> 1748 | BH28: =IF($BK$12=0,BH27+$BH$22,IF($AS$33,(SQRT(($BK$12*$BK$12)-((BG28-$BN$12)*(BG28-$BN$12)))+$BM$12),(-SQRT(($BK$12*$BK$12)-((BG28-$BN$12)*(BG28-$BN$12)))+$BM$12))) -> -209.84314 | BI28: 5 | BJ28: =BJ27+$BK$23 -> -1409.93 | BK28: =IF($BK$13=0,BK27+$BK$22,IF($AT$33,(SQRT(($BK$13*$BK$13)-((BJ28-$BN$13)*(BJ28-$BN$13)))+$BM$13),(-SQRT(($BK$13*$BK$13)-((BJ28-$BN$13)*(BJ28-$BN$13)))+$BM$13))) -> 5134.4691 | BL28: 5 | BM28: =BM27+$BN$23 -> 4543.8549 | BN28: =IF($BK$14=0,BN27+$BN$22,IF($AU$33,(SQRT(($BK$14*$BK$14)-((BM28-$BN$14)*(BM28-$BN$14)))+$BM$14),(-SQRT(($BK$14*$BK$14)-((BM28-$BN$14)*(BM28-$BN$14)))+$BM$14))) -> -4745.3562 | BO28: 5 | BP28: =BP27+$BQ$23 -> -6468.4874 | BQ28: =IF($BK$15=0,BQ27+$BQ$22,IF($AV$33,(SQRT(($BK$15*$BK$15)-((BP28-$BN$15)*(BP28-$BN$15)))+$BM$15),(-SQRT(($BK$15*$BK$15)-((BP28-$BN$15)*(BP28-$BN$15)))+$BM$15))) -> 374.56504 | BR28: 5 | BS28: =BS27+$BT$23 -> -3787.8663 | BT28: =IF($BK$16=0,BT27+$BT$22,IF($AW$33,(SQRT(($BK$16*$BK$16)-((BS28-$BN$16)*(BS28-$BN$16)))+$BM$16),(-SQRT(($BK$16*$BK$16)-((BS28-$BN$16)*(BS28-$BN$16)))+$BM$16))) -> -1231.0378 | BU28: 5 | BV28: =BV27+$BW$23 -> -1371.474 | BW28: =IF($BK$17=0,BW27+$BW$22,IF($AX$33,(SQRT(($BK$17*$BK$17)-((BV28-$BN$17)*(BV28-$BN$17)))+$BM$17),(-SQRT(($BK$17*$BK$17)-((BV28-$BN$17)*(BV28-$BN$17)))+$BM$17))) -> -887.34139 | BX28: 5 | BY28: =BY27+$BZ$23 -> 0 | BZ28: =IF($BK$18=0,BZ27+$BZ$22,IF($AY$33,(SQRT(($BK$18*$BK$18)-((BY28-$BN$18)*(BY28-$BN$18)))+$BM$18),(-SQRT(($BK$18*$BK$18)-((BY28-$BN$18)*(BY28-$BN$18)))+$BM$18))) -> 0 | CA28: 5 | CB28: =CB27+$CC$23 -> 0 | CC28: =IF($BK$19=0,CC27+$CC$22,IF($AZ$33,(SQRT(($BK$19*$BK$19)-((CB28-$BN$19)*(CB28-$BN$19)))+$BM$19),(-SQRT(($BK$19*$BK$19)-((CB28-$BN$19)*(CB28-$BN$19)))+$BM$19))) -> 0
B29: 5 | C29: =IF(G7=5,"C-E",IF(G7=6,"B-E",IF(G7=7,"B-D",IF(G7=8,"A-G","")))) -> B-E | D29: =Print!D32 -> 7390 | Y29: =SQRT((D29*D29)-(AA29*AA29)) -> 7390 | AA29: =VLOOKUP(LEFT(C29,1),HEIGHT,2,FALSE)-VLOOKUP(RIGHT(C29,1),HEIGHT,2,FALSE) -> 0 | AG29: =MAX(AG11:AG18) -> 6902.0366 | AH29: =MAX(AH11:AH18) -> 0 | AM29: =AM27 -> 0 | AN29: =AN27 -> 0 | AZ29: =IF(ISERROR(BB18*F17),0,BB18*F17) -> 0 | BB29: =IF(ISERROR(SQRT((BB18*BB18)+((AB17-BD45)*(AB17-BD45)))),0,SQRT((BB18*BB18)+((AB17-BD45)*(AB17-BD45)))) -> 0 | BD29: =ATAN((BA19-BA18)/(AZ19-AZ18)) -> #DIV/0! | BE29: =BD29*180/PI() -> #DIV/0! | BF29: 6 | BG29: =BG28+$BH$23 -> 2185 | BH29: =IF($BK$12=0,BH28+$BH$22,IF($AS$33,(SQRT(($BK$12*$BK$12)-((BG29-$BN$12)*(BG29-$BN$12)))+$BM$12),(-SQRT(($BK$12*$BK$12)-((BG29-$BN$12)*(BG29-$BN$12)))+$BM$12))) -> -218.5 | BI29: 6 | BJ29: =BJ28+$BK$23 -> -1762.4125 | BK29: =IF($BK$13=0,BK28+$BK$22,IF($AT$33,(SQRT(($BK$13*$BK$13)-((BJ29-$BN$13)*(BJ29-$BN$13)))+$BM$13),(-SQRT(($BK$13*$BK$13)-((BJ29-$BN$13)*(BJ29-$BN$13)))+$BM$13))) -> 5370.1848 | BL29: 6 | BM29: =BM28+$BN$23 -> 3954.3095 | BN29: =IF($BK$14=0,BN28+$BN$22,IF($AU$33,(SQRT(($BK$14*$BK$14)-((BM29-$BN$14)*(BM29-$BN$14)))+$BM$14),(-SQRT(($BK$14*$BK$14)-((BM29-$BN$14)*(BM29-$BN$14)))+$BM$14))) -> -5123.6385 | BO29: 6 | BP29: =BP28+$BQ$23 -> -6188.6146 | BQ29: =IF($BK$15=0,BQ28+$BQ$22,IF($AV$33,(SQRT(($BK$15*$BK$15)-((BP29-$BN$15)*(BP29-$BN$15)))+$BM$15),(-SQRT(($BK$15*$BK$15)-((BP29-$BN$15)*(BP29-$BN$15)))+$BM$15))) -> 180.50085 | BR29: 6 | BS29: =BS28+$BT$23 -> -3537.5202 | BT29: =IF($BK$16=0,BT28+$BT$22,IF($AW$33,(SQRT(($BK$16*$BK$16)-((BS29-$BN$16)*(BS29-$BN$16)))+$BM$16),(-SQRT(($BK$16*$BK$16)-((BS29-$BN$16)*(BS29-$BN$16)))+$BM$16))) -> -1294.4662 | BU29: 6 | BV29: =BV28+$BW$23 -> -1142.895 | BW29: =IF($BK$17=0,BW28+$BW$22,IF($AX$33,(SQRT(($BK$17*$BK$17)-((BV29-$BN$17)*(BV29-$BN$17)))+$BM$17),(-SQRT(($BK$17*$BK$17)-((BV29-$BN$17)*(BV29-$BN$17)))+$BM$17))) -> -707.63434 | BX29: 6 | BY29: =BY28+$BZ$23 -> 0 | BZ29: =IF($BK$18=0,BZ28+$BZ$22,IF($AY$33,(SQRT(($BK$18*$BK$18)-((BY29-$BN$18)*(BY29-$BN$18)))+$BM$18),(-SQRT(($BK$18*$BK$18)-((BY29-$BN$18)*(BY29-$BN$18)))+$BM$18))) -> 0 | CA29: 6 | CB29: =CB28+$CC$23 -> 0 | CC29: =IF($BK$19=0,CC28+$CC$22,IF($AZ$33,(SQRT(($BK$19*$BK$19)-((CB29-$BN$19)*(CB29-$BN$19)))+$BM$19),(-SQRT(($BK$19*$BK$19)-((CB29-$BN$19)*(CB29-$BN$19)))+$BM$19))) -> 0
B30: 6 | C30: =IF(G7=6,"B-F",IF(G7=7,"B-E",IF(G7=8,"B-D",""))) -> B-F | D30: =Print!D33 -> 8020 | Y30: =SQRT((D30*D30)-(AA30*AA30)) -> 8020 | AA30: =VLOOKUP(LEFT(C30,1),HEIGHT,2,FALSE)-VLOOKUP(RIGHT(C30,1),HEIGHT,2,FALSE) -> 0 | AJ30: X | AK30: 0.73333333 | AM30: =IF(G7>7,AG17+AI18,AG17+AI11) -> 0 | AN30: =IF(G7>7,AH17+AJ18,AH17+AJ11) -> 0 | AZ30: =IF(ISERROR(BB19*F18),0,BB19*F18) -> 0 | BB30: =IF(ISERROR(SQRT((BB19*BB19)+((AB18-BD46)*(AB18-BD46)))),0,SQRT((BB19*BB19)+((AB18-BD46)*(AB18-BD46)))) -> 0 | BF30: 7 | BG30: =BG29+$BH$23 -> 2622 | BH30: =IF($BK$12=0,BH29+$BH$22,IF($AS$33,(SQRT(($BK$12*$BK$12)-((BG30-$BN$12)*(BG30-$BN$12)))+$BM$12),(-SQRT(($BK$12*$BK$12)-((BG30-$BN$12)*(BG30-$BN$12)))+$BM$12))) -> -209.84314 | BI30: 7 | BJ30: =BJ29+$BK$23 -> -2114.8949 | BK30: =IF($BK$13=0,BK29+$BK$22,IF($AT$33,(SQRT(($BK$13*$BK$13)-((BJ30-$BN$13)*(BJ30-$BN$13)))+$BM$13),(-SQRT(($BK$13*$BK$13)-((BJ30-$BN$13)*(BJ30-$BN$13)))+$BM$13))) -> 5626.4643 | BL30: 7 | BM30: =BM29+$BN$23 -> 3364.7641 | BN30: =IF($BK$14=0,BN29+$BN$22,IF($AU$33,(SQRT(($BK$14*$BK$14)-((BM30-$BN$14)*(BM30-$BN$14)))+$BM$14),(-SQRT(($BK$14*$BK$14)-((BM30-$BN$14)*(BM30-$BN$14)))+$BM$14))) -> -5535.4612 | BO30: 7 | BP30: =BP29+$BQ$23 -> -5908.7417 | BQ30: =IF($BK$15=0,BQ29+$BQ$22,IF($AV$33,(SQRT(($BK$15*$BK$15)-((BP30-$BN$15)*(BP30-$BN$15)))+$BM$15),(-SQRT(($BK$15*$BK$15)-((BP30-$BN$15)*(BP30-$BN$15)))+$BM$15))) -> -30.274509 | BR30: 7 | BS30: =BS29+$BT$23 -> -3287.1742 | BT30: =IF($BK$16=0,BT29+$BT$22,IF($AW$33,(SQRT(($BK$16*$BK$16)-((BS30-$BN$16)*(BS30-$BN$16)))+$BM$16),(-SQRT(($BK$16*$BK$16)-((BS30-$BN$16)*(BS30-$BN$16)))+$BM$16))) -> -1368.5452 | BU30: 7 | BV30: =BV29+$BW$23 -> -914.31603 | BW30: =IF($BK$17=0,BW29+$BW$22,IF($AX$33,(SQRT(($BK$17*$BK$17)-((BV30-$BN$17)*(BV30-$BN$17)))+$BM$17),(-SQRT(($BK$17*$BK$17)-((BV30-$BN$17)*(BV30-$BN$17)))+$BM$17))) -> -541.98839 | BX30: 7 | BY30: =BY29+$BZ$23 -> 0 | BZ30: =IF($BK$18=0,BZ29+$BZ$22,IF($AY$33,(SQRT(($BK$18*$BK$18)-((BY30-$BN$18)*(BY30-$BN$18)))+$BM$18),(-SQRT(($BK$18*$BK$18)-((BY30-$BN$18)*(BY30-$BN$18)))+$BM$18))) -> 0 | CA30: 7 | CB30: =CB29+$CC$23 -> 0 | CC30: =IF($BK$19=0,CC29+$CC$22,IF($AZ$33,(SQRT(($BK$19*$BK$19)-((CB30-$BN$19)*(CB30-$BN$19)))+$BM$19),(-SQRT(($BK$19*$BK$19)-((CB30-$BN$19)*(CB30-$BN$19)))+$BM$19))) -> 0
B31: 7 | C31: =IF(G7=6,"C-E",IF(G7=7,"B-F",IF(G7=8,"B-E",""))) -> C-E | D31: =Print!D34 -> 8080 | Y31: =SQRT((D31*D31)-(AA31*AA31)) -> 8080 | AA31: =VLOOKUP(LEFT(C31,1),HEIGHT,2,FALSE)-VLOOKUP(RIGHT(C31,1),HEIGHT,2,FALSE) -> 0 | AJ31: Y | AK31: 1.3636364 | AM31: =AG17 -> 0 | AN31: =AH17 -> 0 | BF31: 8 | BG31: =BG30+$BH$23 -> 3059 | BH31: =IF($BK$12=0,BH30+$BH$22,IF($AS$33,(SQRT(($BK$12*$BK$12)-((BG31-$BN$12)*(BG31-$BN$12)))+$BM$12),(-SQRT(($BK$12*$BK$12)-((BG31-$BN$12)*(BG31-$BN$12)))+$BM$12))) -> -183.83168 | BI31: 8 | BJ31: =BJ30+$BK$23 -> -2467.3774 | BK31: =IF($BK$13=0,BK30+$BK$22,IF($AT$33,(SQRT(($BK$13*$BK$13)-((BJ31-$BN$13)*(BJ31-$BN$13)))+$BM$13),(-SQRT(($BK$13*$BK$13)-((BJ31-$BN$13)*(BJ31-$BN$13)))+$BM$13))) -> 5905.1775 | BL31: 8 | BM31: =BM30+$BN$23 -> 2775.2187 | BN31: =IF($BK$14=0,BN30+$BN$22,IF($AU$33,(SQRT(($BK$14*$BK$14)-((BM31-$BN$14)*(BM31-$BN$14)))+$BM$14),(-SQRT(($BK$14*$BK$14)-((BM31-$BN$14)*(BM31-$BN$14)))+$BM$14))) -> -5983.7497 | BO31: 8 | BP31: =BP30+$BQ$23 -> -5628.8689 | BQ31: =IF($BK$15=0,BQ30+$BQ$22,IF($AV$33,(SQRT(($BK$15*$BK$15)-((BP31-$BN$15)*(BP31-$BN$15)))+$BM$15),(-SQRT(($BK$15*$BK$15)-((BP31-$BN$15)*(BP31-$BN$15)))+$BM$15))) -> -259.33719 | BR31: 8 | BS31: =BS30+$BT$23 -> -3036.8282 | BT31: =IF($BK$16=0,BT30+$BT$22,IF($AW$33,(SQRT(($BK$16*$BK$16)-((BS31-$BN$16)*(BS31-$BN$16)))+$BM$16),(-SQRT(($BK$16*$BK$16)-((BS31-$BN$16)*(BS31-$BN$16)))+$BM$16))) -> -1453.6584 | BU31: 8 | BV31: =BV30+$BW$23 -> -685.73702 | BW31: =IF($BK$17=0,BW30+$BW$22,IF($AX$33,(SQRT(($BK$17*$BK$17)-((BV31-$BN$17)*(BV31-$BN$17)))+$BM$17),(-SQRT(($BK$17*$BK$17)-((BV31-$BN$17)*(BV31-$BN$17)))+$BM$17))) -> -389.2688 | BX31: 8 | BY31: =BY30+$BZ$23 -> 0 | BZ31: =IF($BK$18=0,BZ30+$BZ$22,IF($AY$33,(SQRT(($BK$18*$BK$18)-((BY31-$BN$18)*(BY31-$BN$18)))+$BM$18),(-SQRT(($BK$18*$BK$18)-((BY31-$BN$18)*(BY31-$BN$18)))+$BM$18))) -> 0 | CA31: 8 | CB31: =CB30+$CC$23 -> 0 | CC31: =IF($BK$19=0,CC30+$CC$22,IF($AZ$33,(SQRT(($BK$19*$BK$19)-((CB31-$BN$19)*(CB31-$BN$19)))+$BM$19),(-SQRT(($BK$19*$BK$19)-((CB31-$BN$19)*(CB31-$BN$19)))+$BM$19))) -> 0
